Using TensorFlow backend.
WARNING:tensorflow:From /Volumes/Transcend/opt/anaconda3/envs/keras/lib/python3.6/site-packages/tensorflow_core/python/ops/resource_variable_ops.py:1630: calling BaseResourceVariable.__init__ (from tensorflow.python.ops.resource_variable_ops) with constraint is deprecated and will be removed in a future version.
Instructions for updating:
If using Keras pass *_constraint arguments to layers.
Load data...
Adjusting sequence length for actual size
x_train shape: (9595, 56)
x_test shape: (1067, 56)
Vocabulary Size: 18779
Model type is CNN-non-static
Load existing Word2Vec model '50features_1minwords_10context'
Traceback (most recent call last):
  File "sentiment_cnn.py", line 135, in <module>
    z = Embedding(len(vocabulary_inv), embedding_dim, input_length=sequence_length, name="embedding")(model_input)
  File "/Volumes/Transcend/opt/anaconda3/envs/keras/lib/python3.6/site-packages/keras/engine/base_layer.py", line 489, in __call__
    output = self.call(inputs, **kwargs)
  File "/Volumes/Transcend/opt/anaconda3/envs/keras/lib/python3.6/site-packages/keras/layers/embeddings.py", line 144, in call
    out = K.gather(self.embeddings, inputs)
  File "/Volumes/Transcend/opt/anaconda3/envs/keras/lib/python3.6/site-packages/keras/backend/tensorflow_backend.py", line 1629, in gather
    return tf.nn.embedding_lookup(reference, indices)
  File "/Volumes/Transcend/opt/anaconda3/envs/keras/lib/python3.6/site-packages/tensorflow_core/python/ops/embedding_ops.py", line 317, in embedding_lookup
    transform_fn=None)
  File "/Volumes/Transcend/opt/anaconda3/envs/keras/lib/python3.6/site-packages/tensorflow_core/python/ops/embedding_ops.py", line 135, in _embedding_lookup_and_transform
    array_ops.gather(params[0], ids, name=name), ids, max_norm)
  File "/Volumes/Transcend/opt/anaconda3/envs/keras/lib/python3.6/site-packages/tensorflow_core/python/util/dispatch.py", line 180, in wrapper
    return target(*args, **kwargs)
  File "/Volumes/Transcend/opt/anaconda3/envs/keras/lib/python3.6/site-packages/tensorflow_core/python/ops/array_ops.py", line 3953, in gather
    return params.sparse_read(indices, name=name)
  File "/Volumes/Transcend/opt/anaconda3/envs/keras/lib/python3.6/site-packages/tensorflow_core/python/ops/resource_variable_ops.py", line 640, in sparse_read
    self._handle, indices, dtype=self._dtype, name=name)
  File "/Volumes/Transcend/opt/anaconda3/envs/keras/lib/python3.6/site-packages/tensorflow_core/python/ops/gen_resource_variable_ops.py", line 682, in resource_gather
    validate_indices=validate_indices, name=name)
  File "/Volumes/Transcend/opt/anaconda3/envs/keras/lib/python3.6/site-packages/tensorflow_core/python/framework/op_def_library.py", line 632, in _apply_op_helper
    param_name=input_name)
  File "/Volumes/Transcend/opt/anaconda3/envs/keras/lib/python3.6/site-packages/tensorflow_core/python/framework/op_def_library.py", line 61, in _SatisfiesTypeConstraint
    ", ".join(dtypes.as_dtype(x).name for x in allowed_list)))
TypeError: Value passed to parameter 'indices' has DataType float32 not in list of allowed values: int32, int64
