ERROR (theano.gof.opt): SeqOptimizer apply <theano.gof.optdb.EquilibriumDB object at 0x12660c410>
ERROR (theano.gof.opt): Traceback:
ERROR (theano.gof.opt): Traceback (most recent call last):
  File "/Volumes/Transcend/opt/anaconda3/envs/theano/lib/python2.7/site-packages/theano/gof/opt.py", line 251, in apply
    sub_prof = optimizer.optimize(fgraph)
AttributeError: 'EquilibriumDB' object has no attribute 'optimize'

ERROR (theano.gof.opt): SeqOptimizer apply <theano.gof.opt.EquilibriumOptimizer object at 0x1364ad790>
ERROR (theano.gof.opt): Traceback:
ERROR (theano.gof.opt): Traceback (most recent call last):
  File "/Volumes/Transcend/opt/anaconda3/envs/theano/lib/python2.7/site-packages/theano/gof/opt.py", line 251, in apply
    sub_prof = optimizer.optimize(fgraph)
  File "/Volumes/Transcend/opt/anaconda3/envs/theano/lib/python2.7/site-packages/theano/gof/opt.py", line 93, in optimize
    self.add_requirements(fgraph)
  File "/Volumes/Transcend/opt/anaconda3/envs/theano/lib/python2.7/site-packages/theano/gof/opt.py", line 2388, in add_requirements
    opt.add_requirements(fgraph)
AttributeError: 'SequenceDB' object has no attribute 'add_requirements'

ERROR (theano.gof.opt): SeqOptimizer apply <theano.gof.optdb.TopoDB object at 0x114e12550>
ERROR (theano.gof.opt): Traceback:
ERROR (theano.gof.opt): Traceback (most recent call last):
  File "/Volumes/Transcend/opt/anaconda3/envs/theano/lib/python2.7/site-packages/theano/gof/opt.py", line 251, in apply
    sub_prof = optimizer.optimize(fgraph)
AttributeError: 'TopoDB' object has no attribute 'optimize'

ERROR (theano.gof.opt): SeqOptimizer apply <theano.gof.optdb.EquilibriumDB object at 0x114e12690>
ERROR (theano.gof.opt): Traceback:
ERROR (theano.gof.opt): Traceback (most recent call last):
  File "/Volumes/Transcend/opt/anaconda3/envs/theano/lib/python2.7/site-packages/theano/gof/opt.py", line 251, in apply
    sub_prof = optimizer.optimize(fgraph)
AttributeError: 'EquilibriumDB' object has no attribute 'optimize'

ERROR (theano.gof.opt): SeqOptimizer apply <theano.gof.optdb.EquilibriumDB object at 0x114e12a50>
ERROR (theano.gof.opt): Traceback:
ERROR (theano.gof.opt): Traceback (most recent call last):
  File "/Volumes/Transcend/opt/anaconda3/envs/theano/lib/python2.7/site-packages/theano/gof/opt.py", line 251, in apply
    sub_prof = optimizer.optimize(fgraph)
AttributeError: 'EquilibriumDB' object has no attribute 'optimize'

ERROR (theano.gof.opt): SeqOptimizer apply <theano.gof.optdb.EquilibriumDB object at 0x126618510>
ERROR (theano.gof.opt): Traceback:
ERROR (theano.gof.opt): Traceback (most recent call last):
  File "/Volumes/Transcend/opt/anaconda3/envs/theano/lib/python2.7/site-packages/theano/gof/opt.py", line 251, in apply
    sub_prof = optimizer.optimize(fgraph)
AttributeError: 'EquilibriumDB' object has no attribute 'optimize'

ERROR (theano.gof.opt): SeqOptimizer apply SequenceDB (id 4783785552)
  position [('local_dot_to_dot22', 0), ('gemm_optimizer', 10), ('local_dot22_to_dot22scalar', 11), ('local_gemm_to_gemv', 15), ('use_c_blas', 20), ('scipy_blas', 100)]
  names set(['gemm_optimizer', 'local_gemm_to_gemv', 'local_dot_to_dot22', 'scipy_blas', 'use_c_blas', 'local_dot22_to_dot22scalar'])
  db DefaultOrderedDict([('local_dot_to_dot22', OrderedSet([<theano.gof.opt.TopoOptimizer object at 0x11d22ce10>])), ('TopoOptimizer', OrderedSet([<theano.gof.opt.TopoOptimizer object at 0x11d22ce10>, <theano.gof.opt.TopoOptimizer object at 0x126199610>, <theano.gof.opt.TopoOptimizer object at 0x126199890>, <theano.gof.opt.TopoOptimizer object at 0x1261aa790>])), ('fast_run', OrderedSet([<theano.gof.opt.TopoOptimizer object at 0x11d22ce10>, <theano.tensor.blas.GemmOptimizer object at 0x11d22ce50>, <theano.gof.opt.EquilibriumOptimizer object at 0x1261990d0>, <theano.gof.opt.TopoOptimizer object at 0x126199610>, <theano.gof.opt.TopoOptimizer object at 0x126199890>, <theano.gof.opt.TopoOptimizer object at 0x1261aa790>])), ('fast_compile', OrderedSet([<theano.gof.opt.TopoOptimizer object at 0x11d22ce10>])), ('BlasOpt', OrderedSet([<theano.gof.opt.TopoOptimizer object at 0x11d22ce10>, <theano.tensor.blas.GemmOptimizer object at 0x11d22ce50>, <theano.gof.opt.EquilibriumOptimizer object at 0x1261990d0>, <theano.gof.opt.TopoOptimizer object at 0x126199610>, <theano.gof.opt.TopoOptimizer object at 0x126199890>, <theano.gof.opt.TopoOptimizer object at 0x1261aa790>])), ('gemm_optimizer', OrderedSet([<theano.tensor.blas.GemmOptimizer object at 0x11d22ce50>])), ('GemmOptimizer', OrderedSet([<theano.tensor.blas.GemmOptimizer object at 0x11d22ce50>])), ('local_gemm_to_gemv', OrderedSet([<theano.gof.opt.EquilibriumOptimizer object at 0x1261990d0>])), ('EquilibriumOptimizer', OrderedSet([<theano.gof.opt.EquilibriumOptimizer object at 0x1261990d0>])), ('local_dot22_to_dot22scalar', OrderedSet([<theano.gof.opt.TopoOptimizer object at 0x126199610>])), ('scipy_blas', OrderedSet([<theano.gof.opt.TopoOptimizer object at 0x126199890>])), ('use_c_blas', OrderedSet([<theano.gof.opt.TopoOptimizer object at 0x1261aa790>])), ('c_blas', OrderedSet([<theano.gof.opt.TopoOptimizer object at 0x1261aa790>]))])

ERROR (theano.gof.opt): Traceback:
ERROR (theano.gof.opt): Traceback (most recent call last):
  File "/Volumes/Transcend/opt/anaconda3/envs/theano/lib/python2.7/site-packages/theano/gof/opt.py", line 251, in apply
    sub_prof = optimizer.optimize(fgraph)
AttributeError: 'SequenceDB' object has no attribute 'optimize'

ERROR (theano.gof.opt): SeqOptimizer apply <theano.gof.optdb.EquilibriumDB object at 0x114e12b50>
ERROR (theano.gof.opt): Traceback:
ERROR (theano.gof.opt): Traceback (most recent call last):
  File "/Volumes/Transcend/opt/anaconda3/envs/theano/lib/python2.7/site-packages/theano/gof/opt.py", line 251, in apply
    sub_prof = optimizer.optimize(fgraph)
AttributeError: 'EquilibriumDB' object has no attribute 'optimize'

ERROR (theano.gof.opt): SeqOptimizer apply <theano.gof.optdb.EquilibriumDB object at 0x114e12bd0>
ERROR (theano.gof.opt): Traceback:
ERROR (theano.gof.opt): Traceback (most recent call last):
  File "/Volumes/Transcend/opt/anaconda3/envs/theano/lib/python2.7/site-packages/theano/gof/opt.py", line 251, in apply
    sub_prof = optimizer.optimize(fgraph)
AttributeError: 'EquilibriumDB' object has no attribute 'optimize'

ERROR (theano.gof.opt): SeqOptimizer apply <theano.gof.optdb.EquilibriumDB object at 0x114e12c90>
ERROR (theano.gof.opt): Traceback:
ERROR (theano.gof.opt): Traceback (most recent call last):
  File "/Volumes/Transcend/opt/anaconda3/envs/theano/lib/python2.7/site-packages/theano/gof/opt.py", line 251, in apply
    sub_prof = optimizer.optimize(fgraph)
AttributeError: 'EquilibriumDB' object has no attribute 'optimize'

ERROR (theano.gof.opt): SeqOptimizer apply <theano.gof.opt.EquilibriumOptimizer object at 0x1364ad7d0>
ERROR (theano.gof.opt): Traceback:
ERROR (theano.gof.opt): Traceback (most recent call last):
  File "/Volumes/Transcend/opt/anaconda3/envs/theano/lib/python2.7/site-packages/theano/gof/opt.py", line 251, in apply
    sub_prof = optimizer.optimize(fgraph)
  File "/Volumes/Transcend/opt/anaconda3/envs/theano/lib/python2.7/site-packages/theano/gof/opt.py", line 93, in optimize
    self.add_requirements(fgraph)
  File "/Volumes/Transcend/opt/anaconda3/envs/theano/lib/python2.7/site-packages/theano/gof/opt.py", line 2388, in add_requirements
    opt.add_requirements(fgraph)
AttributeError: 'LocalGroupDB' object has no attribute 'add_requirements'

ERROR (theano.gof.opt): SeqOptimizer apply SequenceDB (id 4783573072)
  position [('local_add_mul_fusion', 0), ('composite_elemwise_fusion', 1)]
  names set(['local_add_mul_fusion', 'composite_elemwise_fusion'])
  db DefaultOrderedDict([('local_add_mul_fusion', OrderedSet([<theano.tensor.opt.FusionOptimizer object at 0x11d1f8890>])), ('FusionOptimizer', OrderedSet([<theano.tensor.opt.FusionOptimizer object at 0x11d1f8890>, <theano.tensor.opt.FusionOptimizer object at 0x11d1f8950>])), ('fast_run', OrderedSet([<theano.tensor.opt.FusionOptimizer object at 0x11d1f8890>, <theano.tensor.opt.FusionOptimizer object at 0x11d1f8950>])), ('fusion', OrderedSet([<theano.tensor.opt.FusionOptimizer object at 0x11d1f8890>, <theano.tensor.opt.FusionOptimizer object at 0x11d1f8950>])), ('composite_elemwise_fusion', OrderedSet([<theano.tensor.opt.FusionOptimizer object at 0x11d1f8950>]))])

ERROR (theano.gof.opt): Traceback:
ERROR (theano.gof.opt): Traceback (most recent call last):
  File "/Volumes/Transcend/opt/anaconda3/envs/theano/lib/python2.7/site-packages/theano/gof/opt.py", line 251, in apply
    sub_prof = optimizer.optimize(fgraph)
AttributeError: 'SequenceDB' object has no attribute 'optimize'

ERROR (theano.gof.opt): SeqOptimizer apply <theano.gof.optdb.EquilibriumDB object at 0x12660c410>
ERROR (theano.gof.opt): Traceback:
ERROR (theano.gof.opt): Traceback (most recent call last):
  File "/Volumes/Transcend/opt/anaconda3/envs/theano/lib/python2.7/site-packages/theano/gof/opt.py", line 251, in apply
    sub_prof = optimizer.optimize(fgraph)
AttributeError: 'EquilibriumDB' object has no attribute 'optimize'

ERROR (theano.gof.opt): SeqOptimizer apply <theano.gof.opt.EquilibriumOptimizer object at 0x139032290>
ERROR (theano.gof.opt): Traceback:
ERROR (theano.gof.opt): Traceback (most recent call last):
  File "/Volumes/Transcend/opt/anaconda3/envs/theano/lib/python2.7/site-packages/theano/gof/opt.py", line 251, in apply
    sub_prof = optimizer.optimize(fgraph)
  File "/Volumes/Transcend/opt/anaconda3/envs/theano/lib/python2.7/site-packages/theano/gof/opt.py", line 93, in optimize
    self.add_requirements(fgraph)
  File "/Volumes/Transcend/opt/anaconda3/envs/theano/lib/python2.7/site-packages/theano/gof/opt.py", line 2388, in add_requirements
    opt.add_requirements(fgraph)
AttributeError: 'SequenceDB' object has no attribute 'add_requirements'

ERROR (theano.gof.opt): SeqOptimizer apply <theano.gof.optdb.TopoDB object at 0x114e12550>
ERROR (theano.gof.opt): Traceback:
ERROR (theano.gof.opt): Traceback (most recent call last):
  File "/Volumes/Transcend/opt/anaconda3/envs/theano/lib/python2.7/site-packages/theano/gof/opt.py", line 251, in apply
    sub_prof = optimizer.optimize(fgraph)
AttributeError: 'TopoDB' object has no attribute 'optimize'

ERROR (theano.gof.opt): SeqOptimizer apply <theano.gof.optdb.EquilibriumDB object at 0x114e12690>
ERROR (theano.gof.opt): Traceback:
ERROR (theano.gof.opt): Traceback (most recent call last):
  File "/Volumes/Transcend/opt/anaconda3/envs/theano/lib/python2.7/site-packages/theano/gof/opt.py", line 251, in apply
    sub_prof = optimizer.optimize(fgraph)
AttributeError: 'EquilibriumDB' object has no attribute 'optimize'

ERROR (theano.gof.opt): SeqOptimizer apply <theano.gof.optdb.EquilibriumDB object at 0x114e12a50>
ERROR (theano.gof.opt): Traceback:
ERROR (theano.gof.opt): Traceback (most recent call last):
  File "/Volumes/Transcend/opt/anaconda3/envs/theano/lib/python2.7/site-packages/theano/gof/opt.py", line 251, in apply
    sub_prof = optimizer.optimize(fgraph)
AttributeError: 'EquilibriumDB' object has no attribute 'optimize'

ERROR (theano.gof.opt): SeqOptimizer apply <theano.gof.optdb.EquilibriumDB object at 0x126618510>
ERROR (theano.gof.opt): Traceback:
ERROR (theano.gof.opt): Traceback (most recent call last):
  File "/Volumes/Transcend/opt/anaconda3/envs/theano/lib/python2.7/site-packages/theano/gof/opt.py", line 251, in apply
    sub_prof = optimizer.optimize(fgraph)
AttributeError: 'EquilibriumDB' object has no attribute 'optimize'

ERROR (theano.gof.opt): SeqOptimizer apply SequenceDB (id 4783785552)
  position [('local_dot_to_dot22', 0), ('gemm_optimizer', 10), ('local_dot22_to_dot22scalar', 11), ('local_gemm_to_gemv', 15), ('use_c_blas', 20), ('scipy_blas', 100)]
  names set(['gemm_optimizer', 'local_gemm_to_gemv', 'local_dot_to_dot22', 'scipy_blas', 'use_c_blas', 'local_dot22_to_dot22scalar'])
  db DefaultOrderedDict([('local_dot_to_dot22', OrderedSet([<theano.gof.opt.TopoOptimizer object at 0x11d22ce10>])), ('TopoOptimizer', OrderedSet([<theano.gof.opt.TopoOptimizer object at 0x11d22ce10>, <theano.gof.opt.TopoOptimizer object at 0x126199610>, <theano.gof.opt.TopoOptimizer object at 0x126199890>, <theano.gof.opt.TopoOptimizer object at 0x1261aa790>])), ('fast_run', OrderedSet([<theano.gof.opt.TopoOptimizer object at 0x11d22ce10>, <theano.tensor.blas.GemmOptimizer object at 0x11d22ce50>, <theano.gof.opt.EquilibriumOptimizer object at 0x1261990d0>, <theano.gof.opt.TopoOptimizer object at 0x126199610>, <theano.gof.opt.TopoOptimizer object at 0x126199890>, <theano.gof.opt.TopoOptimizer object at 0x1261aa790>])), ('fast_compile', OrderedSet([<theano.gof.opt.TopoOptimizer object at 0x11d22ce10>])), ('BlasOpt', OrderedSet([<theano.gof.opt.TopoOptimizer object at 0x11d22ce10>, <theano.tensor.blas.GemmOptimizer object at 0x11d22ce50>, <theano.gof.opt.EquilibriumOptimizer object at 0x1261990d0>, <theano.gof.opt.TopoOptimizer object at 0x126199610>, <theano.gof.opt.TopoOptimizer object at 0x126199890>, <theano.gof.opt.TopoOptimizer object at 0x1261aa790>])), ('gemm_optimizer', OrderedSet([<theano.tensor.blas.GemmOptimizer object at 0x11d22ce50>])), ('GemmOptimizer', OrderedSet([<theano.tensor.blas.GemmOptimizer object at 0x11d22ce50>])), ('local_gemm_to_gemv', OrderedSet([<theano.gof.opt.EquilibriumOptimizer object at 0x1261990d0>])), ('EquilibriumOptimizer', OrderedSet([<theano.gof.opt.EquilibriumOptimizer object at 0x1261990d0>])), ('local_dot22_to_dot22scalar', OrderedSet([<theano.gof.opt.TopoOptimizer object at 0x126199610>])), ('scipy_blas', OrderedSet([<theano.gof.opt.TopoOptimizer object at 0x126199890>])), ('use_c_blas', OrderedSet([<theano.gof.opt.TopoOptimizer object at 0x1261aa790>])), ('c_blas', OrderedSet([<theano.gof.opt.TopoOptimizer object at 0x1261aa790>]))])

ERROR (theano.gof.opt): Traceback:
ERROR (theano.gof.opt): Traceback (most recent call last):
  File "/Volumes/Transcend/opt/anaconda3/envs/theano/lib/python2.7/site-packages/theano/gof/opt.py", line 251, in apply
    sub_prof = optimizer.optimize(fgraph)
AttributeError: 'SequenceDB' object has no attribute 'optimize'

ERROR (theano.gof.opt): SeqOptimizer apply <theano.gof.optdb.EquilibriumDB object at 0x114e12b50>
ERROR (theano.gof.opt): Traceback:
ERROR (theano.gof.opt): Traceback (most recent call last):
  File "/Volumes/Transcend/opt/anaconda3/envs/theano/lib/python2.7/site-packages/theano/gof/opt.py", line 251, in apply
    sub_prof = optimizer.optimize(fgraph)
AttributeError: 'EquilibriumDB' object has no attribute 'optimize'

ERROR (theano.gof.opt): SeqOptimizer apply <theano.gof.optdb.EquilibriumDB object at 0x114e12bd0>
ERROR (theano.gof.opt): Traceback:
ERROR (theano.gof.opt): Traceback (most recent call last):
  File "/Volumes/Transcend/opt/anaconda3/envs/theano/lib/python2.7/site-packages/theano/gof/opt.py", line 251, in apply
    sub_prof = optimizer.optimize(fgraph)
AttributeError: 'EquilibriumDB' object has no attribute 'optimize'

ERROR (theano.gof.opt): SeqOptimizer apply <theano.gof.optdb.EquilibriumDB object at 0x114e12c90>
ERROR (theano.gof.opt): Traceback:
ERROR (theano.gof.opt): Traceback (most recent call last):
  File "/Volumes/Transcend/opt/anaconda3/envs/theano/lib/python2.7/site-packages/theano/gof/opt.py", line 251, in apply
    sub_prof = optimizer.optimize(fgraph)
AttributeError: 'EquilibriumDB' object has no attribute 'optimize'

ERROR (theano.gof.opt): SeqOptimizer apply <theano.gof.opt.EquilibriumOptimizer object at 0x13eba1650>
ERROR (theano.gof.opt): Traceback:
ERROR (theano.gof.opt): Traceback (most recent call last):
  File "/Volumes/Transcend/opt/anaconda3/envs/theano/lib/python2.7/site-packages/theano/gof/opt.py", line 251, in apply
    sub_prof = optimizer.optimize(fgraph)
  File "/Volumes/Transcend/opt/anaconda3/envs/theano/lib/python2.7/site-packages/theano/gof/opt.py", line 93, in optimize
    self.add_requirements(fgraph)
  File "/Volumes/Transcend/opt/anaconda3/envs/theano/lib/python2.7/site-packages/theano/gof/opt.py", line 2388, in add_requirements
    opt.add_requirements(fgraph)
AttributeError: 'LocalGroupDB' object has no attribute 'add_requirements'

ERROR (theano.gof.opt): SeqOptimizer apply SequenceDB (id 4783573072)
  position [('local_add_mul_fusion', 0), ('composite_elemwise_fusion', 1)]
  names set(['local_add_mul_fusion', 'composite_elemwise_fusion'])
  db DefaultOrderedDict([('local_add_mul_fusion', OrderedSet([<theano.tensor.opt.FusionOptimizer object at 0x11d1f8890>])), ('FusionOptimizer', OrderedSet([<theano.tensor.opt.FusionOptimizer object at 0x11d1f8890>, <theano.tensor.opt.FusionOptimizer object at 0x11d1f8950>])), ('fast_run', OrderedSet([<theano.tensor.opt.FusionOptimizer object at 0x11d1f8890>, <theano.tensor.opt.FusionOptimizer object at 0x11d1f8950>])), ('fusion', OrderedSet([<theano.tensor.opt.FusionOptimizer object at 0x11d1f8890>, <theano.tensor.opt.FusionOptimizer object at 0x11d1f8950>])), ('composite_elemwise_fusion', OrderedSet([<theano.tensor.opt.FusionOptimizer object at 0x11d1f8950>]))])

ERROR (theano.gof.opt): Traceback:
ERROR (theano.gof.opt): Traceback (most recent call last):
  File "/Volumes/Transcend/opt/anaconda3/envs/theano/lib/python2.7/site-packages/theano/gof/opt.py", line 251, in apply
    sub_prof = optimizer.optimize(fgraph)
AttributeError: 'SequenceDB' object has no attribute 'optimize'

ERROR (theano.gof.opt): SeqOptimizer apply <theano.gof.optdb.EquilibriumDB object at 0x12660c410>
ERROR (theano.gof.opt): Traceback:
ERROR (theano.gof.opt): Traceback (most recent call last):
  File "/Volumes/Transcend/opt/anaconda3/envs/theano/lib/python2.7/site-packages/theano/gof/opt.py", line 251, in apply
    sub_prof = optimizer.optimize(fgraph)
AttributeError: 'EquilibriumDB' object has no attribute 'optimize'

ERROR (theano.gof.opt): SeqOptimizer apply <theano.gof.opt.EquilibriumOptimizer object at 0x138e80650>
ERROR (theano.gof.opt): Traceback:
ERROR (theano.gof.opt): Traceback (most recent call last):
  File "/Volumes/Transcend/opt/anaconda3/envs/theano/lib/python2.7/site-packages/theano/gof/opt.py", line 251, in apply
    sub_prof = optimizer.optimize(fgraph)
  File "/Volumes/Transcend/opt/anaconda3/envs/theano/lib/python2.7/site-packages/theano/gof/opt.py", line 93, in optimize
    self.add_requirements(fgraph)
  File "/Volumes/Transcend/opt/anaconda3/envs/theano/lib/python2.7/site-packages/theano/gof/opt.py", line 2388, in add_requirements
    opt.add_requirements(fgraph)
AttributeError: 'SequenceDB' object has no attribute 'add_requirements'

ERROR (theano.gof.opt): SeqOptimizer apply <theano.gof.optdb.TopoDB object at 0x114e12550>
ERROR (theano.gof.opt): Traceback:
ERROR (theano.gof.opt): Traceback (most recent call last):
  File "/Volumes/Transcend/opt/anaconda3/envs/theano/lib/python2.7/site-packages/theano/gof/opt.py", line 251, in apply
    sub_prof = optimizer.optimize(fgraph)
AttributeError: 'TopoDB' object has no attribute 'optimize'

ERROR (theano.gof.opt): SeqOptimizer apply <theano.gof.optdb.EquilibriumDB object at 0x114e12690>
ERROR (theano.gof.opt): Traceback:
ERROR (theano.gof.opt): Traceback (most recent call last):
  File "/Volumes/Transcend/opt/anaconda3/envs/theano/lib/python2.7/site-packages/theano/gof/opt.py", line 251, in apply
    sub_prof = optimizer.optimize(fgraph)
AttributeError: 'EquilibriumDB' object has no attribute 'optimize'

ERROR (theano.gof.opt): SeqOptimizer apply <theano.gof.optdb.EquilibriumDB object at 0x114e12a50>
ERROR (theano.gof.opt): Traceback:
ERROR (theano.gof.opt): Traceback (most recent call last):
  File "/Volumes/Transcend/opt/anaconda3/envs/theano/lib/python2.7/site-packages/theano/gof/opt.py", line 251, in apply
    sub_prof = optimizer.optimize(fgraph)
AttributeError: 'EquilibriumDB' object has no attribute 'optimize'

ERROR (theano.gof.opt): SeqOptimizer apply <theano.gof.optdb.EquilibriumDB object at 0x126618510>
ERROR (theano.gof.opt): Traceback:
ERROR (theano.gof.opt): Traceback (most recent call last):
  File "/Volumes/Transcend/opt/anaconda3/envs/theano/lib/python2.7/site-packages/theano/gof/opt.py", line 251, in apply
    sub_prof = optimizer.optimize(fgraph)
AttributeError: 'EquilibriumDB' object has no attribute 'optimize'

ERROR (theano.gof.opt): SeqOptimizer apply SequenceDB (id 4783785552)
  position [('local_dot_to_dot22', 0), ('gemm_optimizer', 10), ('local_dot22_to_dot22scalar', 11), ('local_gemm_to_gemv', 15), ('use_c_blas', 20), ('scipy_blas', 100)]
  names set(['gemm_optimizer', 'local_gemm_to_gemv', 'local_dot_to_dot22', 'scipy_blas', 'use_c_blas', 'local_dot22_to_dot22scalar'])
  db DefaultOrderedDict([('local_dot_to_dot22', OrderedSet([<theano.gof.opt.TopoOptimizer object at 0x11d22ce10>])), ('TopoOptimizer', OrderedSet([<theano.gof.opt.TopoOptimizer object at 0x11d22ce10>, <theano.gof.opt.TopoOptimizer object at 0x126199610>, <theano.gof.opt.TopoOptimizer object at 0x126199890>, <theano.gof.opt.TopoOptimizer object at 0x1261aa790>])), ('fast_run', OrderedSet([<theano.gof.opt.TopoOptimizer object at 0x11d22ce10>, <theano.tensor.blas.GemmOptimizer object at 0x11d22ce50>, <theano.gof.opt.EquilibriumOptimizer object at 0x1261990d0>, <theano.gof.opt.TopoOptimizer object at 0x126199610>, <theano.gof.opt.TopoOptimizer object at 0x126199890>, <theano.gof.opt.TopoOptimizer object at 0x1261aa790>])), ('fast_compile', OrderedSet([<theano.gof.opt.TopoOptimizer object at 0x11d22ce10>])), ('BlasOpt', OrderedSet([<theano.gof.opt.TopoOptimizer object at 0x11d22ce10>, <theano.tensor.blas.GemmOptimizer object at 0x11d22ce50>, <theano.gof.opt.EquilibriumOptimizer object at 0x1261990d0>, <theano.gof.opt.TopoOptimizer object at 0x126199610>, <theano.gof.opt.TopoOptimizer object at 0x126199890>, <theano.gof.opt.TopoOptimizer object at 0x1261aa790>])), ('gemm_optimizer', OrderedSet([<theano.tensor.blas.GemmOptimizer object at 0x11d22ce50>])), ('GemmOptimizer', OrderedSet([<theano.tensor.blas.GemmOptimizer object at 0x11d22ce50>])), ('local_gemm_to_gemv', OrderedSet([<theano.gof.opt.EquilibriumOptimizer object at 0x1261990d0>])), ('EquilibriumOptimizer', OrderedSet([<theano.gof.opt.EquilibriumOptimizer object at 0x1261990d0>])), ('local_dot22_to_dot22scalar', OrderedSet([<theano.gof.opt.TopoOptimizer object at 0x126199610>])), ('scipy_blas', OrderedSet([<theano.gof.opt.TopoOptimizer object at 0x126199890>])), ('use_c_blas', OrderedSet([<theano.gof.opt.TopoOptimizer object at 0x1261aa790>])), ('c_blas', OrderedSet([<theano.gof.opt.TopoOptimizer object at 0x1261aa790>]))])

ERROR (theano.gof.opt): Traceback:
ERROR (theano.gof.opt): Traceback (most recent call last):
  File "/Volumes/Transcend/opt/anaconda3/envs/theano/lib/python2.7/site-packages/theano/gof/opt.py", line 251, in apply
    sub_prof = optimizer.optimize(fgraph)
AttributeError: 'SequenceDB' object has no attribute 'optimize'

ERROR (theano.gof.opt): SeqOptimizer apply <theano.gof.optdb.EquilibriumDB object at 0x114e12b50>
ERROR (theano.gof.opt): Traceback:
ERROR (theano.gof.opt): Traceback (most recent call last):
  File "/Volumes/Transcend/opt/anaconda3/envs/theano/lib/python2.7/site-packages/theano/gof/opt.py", line 251, in apply
    sub_prof = optimizer.optimize(fgraph)
AttributeError: 'EquilibriumDB' object has no attribute 'optimize'

ERROR (theano.gof.opt): SeqOptimizer apply <theano.gof.optdb.EquilibriumDB object at 0x114e12bd0>
ERROR (theano.gof.opt): Traceback:
ERROR (theano.gof.opt): Traceback (most recent call last):
  File "/Volumes/Transcend/opt/anaconda3/envs/theano/lib/python2.7/site-packages/theano/gof/opt.py", line 251, in apply
    sub_prof = optimizer.optimize(fgraph)
AttributeError: 'EquilibriumDB' object has no attribute 'optimize'

ERROR (theano.gof.opt): SeqOptimizer apply <theano.gof.optdb.EquilibriumDB object at 0x114e12c90>
ERROR (theano.gof.opt): Traceback:
ERROR (theano.gof.opt): Traceback (most recent call last):
  File "/Volumes/Transcend/opt/anaconda3/envs/theano/lib/python2.7/site-packages/theano/gof/opt.py", line 251, in apply
    sub_prof = optimizer.optimize(fgraph)
AttributeError: 'EquilibriumDB' object has no attribute 'optimize'

ERROR (theano.gof.opt): SeqOptimizer apply <theano.gof.opt.EquilibriumOptimizer object at 0x138e80090>
ERROR (theano.gof.opt): Traceback:
ERROR (theano.gof.opt): Traceback (most recent call last):
  File "/Volumes/Transcend/opt/anaconda3/envs/theano/lib/python2.7/site-packages/theano/gof/opt.py", line 251, in apply
    sub_prof = optimizer.optimize(fgraph)
  File "/Volumes/Transcend/opt/anaconda3/envs/theano/lib/python2.7/site-packages/theano/gof/opt.py", line 93, in optimize
    self.add_requirements(fgraph)
  File "/Volumes/Transcend/opt/anaconda3/envs/theano/lib/python2.7/site-packages/theano/gof/opt.py", line 2388, in add_requirements
    opt.add_requirements(fgraph)
AttributeError: 'LocalGroupDB' object has no attribute 'add_requirements'

ERROR (theano.gof.opt): SeqOptimizer apply SequenceDB (id 4783573072)
  position [('local_add_mul_fusion', 0), ('composite_elemwise_fusion', 1)]
  names set(['local_add_mul_fusion', 'composite_elemwise_fusion'])
  db DefaultOrderedDict([('local_add_mul_fusion', OrderedSet([<theano.tensor.opt.FusionOptimizer object at 0x11d1f8890>])), ('FusionOptimizer', OrderedSet([<theano.tensor.opt.FusionOptimizer object at 0x11d1f8890>, <theano.tensor.opt.FusionOptimizer object at 0x11d1f8950>])), ('fast_run', OrderedSet([<theano.tensor.opt.FusionOptimizer object at 0x11d1f8890>, <theano.tensor.opt.FusionOptimizer object at 0x11d1f8950>])), ('fusion', OrderedSet([<theano.tensor.opt.FusionOptimizer object at 0x11d1f8890>, <theano.tensor.opt.FusionOptimizer object at 0x11d1f8950>])), ('composite_elemwise_fusion', OrderedSet([<theano.tensor.opt.FusionOptimizer object at 0x11d1f8950>]))])

ERROR (theano.gof.opt): Traceback:
ERROR (theano.gof.opt): Traceback (most recent call last):
  File "/Volumes/Transcend/opt/anaconda3/envs/theano/lib/python2.7/site-packages/theano/gof/opt.py", line 251, in apply
    sub_prof = optimizer.optimize(fgraph)
AttributeError: 'SequenceDB' object has no attribute 'optimize'

ERROR (theano.gof.opt): SeqOptimizer apply <theano.gof.optdb.EquilibriumDB object at 0x12660c410>
ERROR (theano.gof.opt): Traceback:
ERROR (theano.gof.opt): Traceback (most recent call last):
  File "/Volumes/Transcend/opt/anaconda3/envs/theano/lib/python2.7/site-packages/theano/gof/opt.py", line 251, in apply
    sub_prof = optimizer.optimize(fgraph)
AttributeError: 'EquilibriumDB' object has no attribute 'optimize'

ERROR (theano.gof.opt): SeqOptimizer apply <theano.gof.opt.EquilibriumOptimizer object at 0x140176350>
ERROR (theano.gof.opt): Traceback:
ERROR (theano.gof.opt): Traceback (most recent call last):
  File "/Volumes/Transcend/opt/anaconda3/envs/theano/lib/python2.7/site-packages/theano/gof/opt.py", line 251, in apply
    sub_prof = optimizer.optimize(fgraph)
  File "/Volumes/Transcend/opt/anaconda3/envs/theano/lib/python2.7/site-packages/theano/gof/opt.py", line 93, in optimize
    self.add_requirements(fgraph)
  File "/Volumes/Transcend/opt/anaconda3/envs/theano/lib/python2.7/site-packages/theano/gof/opt.py", line 2388, in add_requirements
    opt.add_requirements(fgraph)
AttributeError: 'SequenceDB' object has no attribute 'add_requirements'

ERROR (theano.gof.opt): SeqOptimizer apply <theano.gof.optdb.TopoDB object at 0x114e12550>
ERROR (theano.gof.opt): Traceback:
ERROR (theano.gof.opt): Traceback (most recent call last):
  File "/Volumes/Transcend/opt/anaconda3/envs/theano/lib/python2.7/site-packages/theano/gof/opt.py", line 251, in apply
    sub_prof = optimizer.optimize(fgraph)
AttributeError: 'TopoDB' object has no attribute 'optimize'

ERROR (theano.gof.opt): SeqOptimizer apply <theano.gof.optdb.EquilibriumDB object at 0x114e12690>
ERROR (theano.gof.opt): Traceback:
ERROR (theano.gof.opt): Traceback (most recent call last):
  File "/Volumes/Transcend/opt/anaconda3/envs/theano/lib/python2.7/site-packages/theano/gof/opt.py", line 251, in apply
    sub_prof = optimizer.optimize(fgraph)
AttributeError: 'EquilibriumDB' object has no attribute 'optimize'

ERROR (theano.gof.opt): SeqOptimizer apply <theano.gof.optdb.EquilibriumDB object at 0x114e12a50>
ERROR (theano.gof.opt): Traceback:
ERROR (theano.gof.opt): Traceback (most recent call last):
  File "/Volumes/Transcend/opt/anaconda3/envs/theano/lib/python2.7/site-packages/theano/gof/opt.py", line 251, in apply
    sub_prof = optimizer.optimize(fgraph)
AttributeError: 'EquilibriumDB' object has no attribute 'optimize'

ERROR (theano.gof.opt): SeqOptimizer apply <theano.gof.optdb.EquilibriumDB object at 0x126618510>
ERROR (theano.gof.opt): Traceback:
ERROR (theano.gof.opt): Traceback (most recent call last):
  File "/Volumes/Transcend/opt/anaconda3/envs/theano/lib/python2.7/site-packages/theano/gof/opt.py", line 251, in apply
    sub_prof = optimizer.optimize(fgraph)
AttributeError: 'EquilibriumDB' object has no attribute 'optimize'

ERROR (theano.gof.opt): SeqOptimizer apply SequenceDB (id 4783785552)
  position [('local_dot_to_dot22', 0), ('gemm_optimizer', 10), ('local_dot22_to_dot22scalar', 11), ('local_gemm_to_gemv', 15), ('use_c_blas', 20), ('scipy_blas', 100)]
  names set(['gemm_optimizer', 'local_gemm_to_gemv', 'local_dot_to_dot22', 'scipy_blas', 'use_c_blas', 'local_dot22_to_dot22scalar'])
  db DefaultOrderedDict([('local_dot_to_dot22', OrderedSet([<theano.gof.opt.TopoOptimizer object at 0x11d22ce10>])), ('TopoOptimizer', OrderedSet([<theano.gof.opt.TopoOptimizer object at 0x11d22ce10>, <theano.gof.opt.TopoOptimizer object at 0x126199610>, <theano.gof.opt.TopoOptimizer object at 0x126199890>, <theano.gof.opt.TopoOptimizer object at 0x1261aa790>])), ('fast_run', OrderedSet([<theano.gof.opt.TopoOptimizer object at 0x11d22ce10>, <theano.tensor.blas.GemmOptimizer object at 0x11d22ce50>, <theano.gof.opt.EquilibriumOptimizer object at 0x1261990d0>, <theano.gof.opt.TopoOptimizer object at 0x126199610>, <theano.gof.opt.TopoOptimizer object at 0x126199890>, <theano.gof.opt.TopoOptimizer object at 0x1261aa790>])), ('fast_compile', OrderedSet([<theano.gof.opt.TopoOptimizer object at 0x11d22ce10>])), ('BlasOpt', OrderedSet([<theano.gof.opt.TopoOptimizer object at 0x11d22ce10>, <theano.tensor.blas.GemmOptimizer object at 0x11d22ce50>, <theano.gof.opt.EquilibriumOptimizer object at 0x1261990d0>, <theano.gof.opt.TopoOptimizer object at 0x126199610>, <theano.gof.opt.TopoOptimizer object at 0x126199890>, <theano.gof.opt.TopoOptimizer object at 0x1261aa790>])), ('gemm_optimizer', OrderedSet([<theano.tensor.blas.GemmOptimizer object at 0x11d22ce50>])), ('GemmOptimizer', OrderedSet([<theano.tensor.blas.GemmOptimizer object at 0x11d22ce50>])), ('local_gemm_to_gemv', OrderedSet([<theano.gof.opt.EquilibriumOptimizer object at 0x1261990d0>])), ('EquilibriumOptimizer', OrderedSet([<theano.gof.opt.EquilibriumOptimizer object at 0x1261990d0>])), ('local_dot22_to_dot22scalar', OrderedSet([<theano.gof.opt.TopoOptimizer object at 0x126199610>])), ('scipy_blas', OrderedSet([<theano.gof.opt.TopoOptimizer object at 0x126199890>])), ('use_c_blas', OrderedSet([<theano.gof.opt.TopoOptimizer object at 0x1261aa790>])), ('c_blas', OrderedSet([<theano.gof.opt.TopoOptimizer object at 0x1261aa790>]))])

ERROR (theano.gof.opt): Traceback:
ERROR (theano.gof.opt): Traceback (most recent call last):
  File "/Volumes/Transcend/opt/anaconda3/envs/theano/lib/python2.7/site-packages/theano/gof/opt.py", line 251, in apply
    sub_prof = optimizer.optimize(fgraph)
AttributeError: 'SequenceDB' object has no attribute 'optimize'

ERROR (theano.gof.opt): SeqOptimizer apply <theano.gof.optdb.EquilibriumDB object at 0x114e12b50>
ERROR (theano.gof.opt): Traceback:
ERROR (theano.gof.opt): Traceback (most recent call last):
  File "/Volumes/Transcend/opt/anaconda3/envs/theano/lib/python2.7/site-packages/theano/gof/opt.py", line 251, in apply
    sub_prof = optimizer.optimize(fgraph)
AttributeError: 'EquilibriumDB' object has no attribute 'optimize'

ERROR (theano.gof.opt): SeqOptimizer apply <theano.gof.optdb.EquilibriumDB object at 0x114e12bd0>
ERROR (theano.gof.opt): Traceback:
ERROR (theano.gof.opt): Traceback (most recent call last):
  File "/Volumes/Transcend/opt/anaconda3/envs/theano/lib/python2.7/site-packages/theano/gof/opt.py", line 251, in apply
    sub_prof = optimizer.optimize(fgraph)
AttributeError: 'EquilibriumDB' object has no attribute 'optimize'

ERROR (theano.gof.opt): SeqOptimizer apply <theano.gof.optdb.EquilibriumDB object at 0x114e12c90>
ERROR (theano.gof.opt): Traceback:
ERROR (theano.gof.opt): Traceback (most recent call last):
  File "/Volumes/Transcend/opt/anaconda3/envs/theano/lib/python2.7/site-packages/theano/gof/opt.py", line 251, in apply
    sub_prof = optimizer.optimize(fgraph)
AttributeError: 'EquilibriumDB' object has no attribute 'optimize'

ERROR (theano.gof.opt): SeqOptimizer apply <theano.gof.opt.EquilibriumOptimizer object at 0x140176390>
ERROR (theano.gof.opt): Traceback:
ERROR (theano.gof.opt): Traceback (most recent call last):
  File "/Volumes/Transcend/opt/anaconda3/envs/theano/lib/python2.7/site-packages/theano/gof/opt.py", line 251, in apply
    sub_prof = optimizer.optimize(fgraph)
  File "/Volumes/Transcend/opt/anaconda3/envs/theano/lib/python2.7/site-packages/theano/gof/opt.py", line 93, in optimize
    self.add_requirements(fgraph)
  File "/Volumes/Transcend/opt/anaconda3/envs/theano/lib/python2.7/site-packages/theano/gof/opt.py", line 2388, in add_requirements
    opt.add_requirements(fgraph)
AttributeError: 'LocalGroupDB' object has no attribute 'add_requirements'

ERROR (theano.gof.opt): SeqOptimizer apply SequenceDB (id 4783573072)
  position [('local_add_mul_fusion', 0), ('composite_elemwise_fusion', 1)]
  names set(['local_add_mul_fusion', 'composite_elemwise_fusion'])
  db DefaultOrderedDict([('local_add_mul_fusion', OrderedSet([<theano.tensor.opt.FusionOptimizer object at 0x11d1f8890>])), ('FusionOptimizer', OrderedSet([<theano.tensor.opt.FusionOptimizer object at 0x11d1f8890>, <theano.tensor.opt.FusionOptimizer object at 0x11d1f8950>])), ('fast_run', OrderedSet([<theano.tensor.opt.FusionOptimizer object at 0x11d1f8890>, <theano.tensor.opt.FusionOptimizer object at 0x11d1f8950>])), ('fusion', OrderedSet([<theano.tensor.opt.FusionOptimizer object at 0x11d1f8890>, <theano.tensor.opt.FusionOptimizer object at 0x11d1f8950>])), ('composite_elemwise_fusion', OrderedSet([<theano.tensor.opt.FusionOptimizer object at 0x11d1f8950>]))])

ERROR (theano.gof.opt): Traceback:
ERROR (theano.gof.opt): Traceback (most recent call last):
  File "/Volumes/Transcend/opt/anaconda3/envs/theano/lib/python2.7/site-packages/theano/gof/opt.py", line 251, in apply
    sub_prof = optimizer.optimize(fgraph)
AttributeError: 'SequenceDB' object has no attribute 'optimize'

ERROR (theano.gof.opt): SeqOptimizer apply <theano.gof.optdb.EquilibriumDB object at 0x12660c410>
ERROR (theano.gof.opt): Traceback:
ERROR (theano.gof.opt): Traceback (most recent call last):
  File "/Volumes/Transcend/opt/anaconda3/envs/theano/lib/python2.7/site-packages/theano/gof/opt.py", line 251, in apply
    sub_prof = optimizer.optimize(fgraph)
AttributeError: 'EquilibriumDB' object has no attribute 'optimize'

ERROR (theano.gof.opt): SeqOptimizer apply <theano.gof.opt.EquilibriumOptimizer object at 0x126ea9790>
ERROR (theano.gof.opt): Traceback:
ERROR (theano.gof.opt): Traceback (most recent call last):
  File "/Volumes/Transcend/opt/anaconda3/envs/theano/lib/python2.7/site-packages/theano/gof/opt.py", line 251, in apply
    sub_prof = optimizer.optimize(fgraph)
  File "/Volumes/Transcend/opt/anaconda3/envs/theano/lib/python2.7/site-packages/theano/gof/opt.py", line 93, in optimize
    self.add_requirements(fgraph)
  File "/Volumes/Transcend/opt/anaconda3/envs/theano/lib/python2.7/site-packages/theano/gof/opt.py", line 2388, in add_requirements
    opt.add_requirements(fgraph)
AttributeError: 'SequenceDB' object has no attribute 'add_requirements'

ERROR (theano.gof.opt): SeqOptimizer apply <theano.gof.optdb.TopoDB object at 0x114e12550>
ERROR (theano.gof.opt): Traceback:
ERROR (theano.gof.opt): Traceback (most recent call last):
  File "/Volumes/Transcend/opt/anaconda3/envs/theano/lib/python2.7/site-packages/theano/gof/opt.py", line 251, in apply
    sub_prof = optimizer.optimize(fgraph)
AttributeError: 'TopoDB' object has no attribute 'optimize'

ERROR (theano.gof.opt): SeqOptimizer apply <theano.gof.optdb.EquilibriumDB object at 0x114e12690>
ERROR (theano.gof.opt): Traceback:
ERROR (theano.gof.opt): Traceback (most recent call last):
  File "/Volumes/Transcend/opt/anaconda3/envs/theano/lib/python2.7/site-packages/theano/gof/opt.py", line 251, in apply
    sub_prof = optimizer.optimize(fgraph)
AttributeError: 'EquilibriumDB' object has no attribute 'optimize'

ERROR (theano.gof.opt): SeqOptimizer apply <theano.gof.optdb.EquilibriumDB object at 0x114e12a50>
ERROR (theano.gof.opt): Traceback:
ERROR (theano.gof.opt): Traceback (most recent call last):
  File "/Volumes/Transcend/opt/anaconda3/envs/theano/lib/python2.7/site-packages/theano/gof/opt.py", line 251, in apply
    sub_prof = optimizer.optimize(fgraph)
AttributeError: 'EquilibriumDB' object has no attribute 'optimize'

ERROR (theano.gof.opt): SeqOptimizer apply <theano.gof.optdb.EquilibriumDB object at 0x126618510>
ERROR (theano.gof.opt): Traceback:
ERROR (theano.gof.opt): Traceback (most recent call last):
  File "/Volumes/Transcend/opt/anaconda3/envs/theano/lib/python2.7/site-packages/theano/gof/opt.py", line 251, in apply
    sub_prof = optimizer.optimize(fgraph)
AttributeError: 'EquilibriumDB' object has no attribute 'optimize'

ERROR (theano.gof.opt): SeqOptimizer apply SequenceDB (id 4783785552)
  position [('local_dot_to_dot22', 0), ('gemm_optimizer', 10), ('local_dot22_to_dot22scalar', 11), ('local_gemm_to_gemv', 15), ('use_c_blas', 20), ('scipy_blas', 100)]
  names set(['gemm_optimizer', 'local_gemm_to_gemv', 'local_dot_to_dot22', 'scipy_blas', 'use_c_blas', 'local_dot22_to_dot22scalar'])
  db DefaultOrderedDict([('local_dot_to_dot22', OrderedSet([<theano.gof.opt.TopoOptimizer object at 0x11d22ce10>])), ('TopoOptimizer', OrderedSet([<theano.gof.opt.TopoOptimizer object at 0x11d22ce10>, <theano.gof.opt.TopoOptimizer object at 0x126199610>, <theano.gof.opt.TopoOptimizer object at 0x126199890>, <theano.gof.opt.TopoOptimizer object at 0x1261aa790>])), ('fast_run', OrderedSet([<theano.gof.opt.TopoOptimizer object at 0x11d22ce10>, <theano.tensor.blas.GemmOptimizer object at 0x11d22ce50>, <theano.gof.opt.EquilibriumOptimizer object at 0x1261990d0>, <theano.gof.opt.TopoOptimizer object at 0x126199610>, <theano.gof.opt.TopoOptimizer object at 0x126199890>, <theano.gof.opt.TopoOptimizer object at 0x1261aa790>])), ('fast_compile', OrderedSet([<theano.gof.opt.TopoOptimizer object at 0x11d22ce10>])), ('BlasOpt', OrderedSet([<theano.gof.opt.TopoOptimizer object at 0x11d22ce10>, <theano.tensor.blas.GemmOptimizer object at 0x11d22ce50>, <theano.gof.opt.EquilibriumOptimizer object at 0x1261990d0>, <theano.gof.opt.TopoOptimizer object at 0x126199610>, <theano.gof.opt.TopoOptimizer object at 0x126199890>, <theano.gof.opt.TopoOptimizer object at 0x1261aa790>])), ('gemm_optimizer', OrderedSet([<theano.tensor.blas.GemmOptimizer object at 0x11d22ce50>])), ('GemmOptimizer', OrderedSet([<theano.tensor.blas.GemmOptimizer object at 0x11d22ce50>])), ('local_gemm_to_gemv', OrderedSet([<theano.gof.opt.EquilibriumOptimizer object at 0x1261990d0>])), ('EquilibriumOptimizer', OrderedSet([<theano.gof.opt.EquilibriumOptimizer object at 0x1261990d0>])), ('local_dot22_to_dot22scalar', OrderedSet([<theano.gof.opt.TopoOptimizer object at 0x126199610>])), ('scipy_blas', OrderedSet([<theano.gof.opt.TopoOptimizer object at 0x126199890>])), ('use_c_blas', OrderedSet([<theano.gof.opt.TopoOptimizer object at 0x1261aa790>])), ('c_blas', OrderedSet([<theano.gof.opt.TopoOptimizer object at 0x1261aa790>]))])

ERROR (theano.gof.opt): Traceback:
ERROR (theano.gof.opt): Traceback (most recent call last):
  File "/Volumes/Transcend/opt/anaconda3/envs/theano/lib/python2.7/site-packages/theano/gof/opt.py", line 251, in apply
    sub_prof = optimizer.optimize(fgraph)
AttributeError: 'SequenceDB' object has no attribute 'optimize'

ERROR (theano.gof.opt): SeqOptimizer apply <theano.gof.optdb.EquilibriumDB object at 0x114e12b50>
ERROR (theano.gof.opt): Traceback:
ERROR (theano.gof.opt): Traceback (most recent call last):
  File "/Volumes/Transcend/opt/anaconda3/envs/theano/lib/python2.7/site-packages/theano/gof/opt.py", line 251, in apply
    sub_prof = optimizer.optimize(fgraph)
AttributeError: 'EquilibriumDB' object has no attribute 'optimize'

ERROR (theano.gof.opt): SeqOptimizer apply <theano.gof.optdb.EquilibriumDB object at 0x114e12bd0>
ERROR (theano.gof.opt): Traceback:
ERROR (theano.gof.opt): Traceback (most recent call last):
  File "/Volumes/Transcend/opt/anaconda3/envs/theano/lib/python2.7/site-packages/theano/gof/opt.py", line 251, in apply
    sub_prof = optimizer.optimize(fgraph)
AttributeError: 'EquilibriumDB' object has no attribute 'optimize'

ERROR (theano.gof.opt): SeqOptimizer apply <theano.gof.optdb.EquilibriumDB object at 0x114e12c90>
ERROR (theano.gof.opt): Traceback:
ERROR (theano.gof.opt): Traceback (most recent call last):
  File "/Volumes/Transcend/opt/anaconda3/envs/theano/lib/python2.7/site-packages/theano/gof/opt.py", line 251, in apply
    sub_prof = optimizer.optimize(fgraph)
AttributeError: 'EquilibriumDB' object has no attribute 'optimize'

ERROR (theano.gof.opt): SeqOptimizer apply <theano.gof.opt.EquilibriumOptimizer object at 0x126ea9890>
ERROR (theano.gof.opt): Traceback:
ERROR (theano.gof.opt): Traceback (most recent call last):
  File "/Volumes/Transcend/opt/anaconda3/envs/theano/lib/python2.7/site-packages/theano/gof/opt.py", line 251, in apply
    sub_prof = optimizer.optimize(fgraph)
  File "/Volumes/Transcend/opt/anaconda3/envs/theano/lib/python2.7/site-packages/theano/gof/opt.py", line 93, in optimize
    self.add_requirements(fgraph)
  File "/Volumes/Transcend/opt/anaconda3/envs/theano/lib/python2.7/site-packages/theano/gof/opt.py", line 2388, in add_requirements
    opt.add_requirements(fgraph)
AttributeError: 'LocalGroupDB' object has no attribute 'add_requirements'

ERROR (theano.gof.opt): SeqOptimizer apply SequenceDB (id 4783573072)
  position [('local_add_mul_fusion', 0), ('composite_elemwise_fusion', 1)]
  names set(['local_add_mul_fusion', 'composite_elemwise_fusion'])
  db DefaultOrderedDict([('local_add_mul_fusion', OrderedSet([<theano.tensor.opt.FusionOptimizer object at 0x11d1f8890>])), ('FusionOptimizer', OrderedSet([<theano.tensor.opt.FusionOptimizer object at 0x11d1f8890>, <theano.tensor.opt.FusionOptimizer object at 0x11d1f8950>])), ('fast_run', OrderedSet([<theano.tensor.opt.FusionOptimizer object at 0x11d1f8890>, <theano.tensor.opt.FusionOptimizer object at 0x11d1f8950>])), ('fusion', OrderedSet([<theano.tensor.opt.FusionOptimizer object at 0x11d1f8890>, <theano.tensor.opt.FusionOptimizer object at 0x11d1f8950>])), ('composite_elemwise_fusion', OrderedSet([<theano.tensor.opt.FusionOptimizer object at 0x11d1f8950>]))])

ERROR (theano.gof.opt): Traceback:
ERROR (theano.gof.opt): Traceback (most recent call last):
  File "/Volumes/Transcend/opt/anaconda3/envs/theano/lib/python2.7/site-packages/theano/gof/opt.py", line 251, in apply
    sub_prof = optimizer.optimize(fgraph)
AttributeError: 'SequenceDB' object has no attribute 'optimize'

ERROR (theano.gof.opt): SeqOptimizer apply <theano.gof.optdb.EquilibriumDB object at 0x12660c410>
ERROR (theano.gof.opt): Traceback:
ERROR (theano.gof.opt): Traceback (most recent call last):
  File "/Volumes/Transcend/opt/anaconda3/envs/theano/lib/python2.7/site-packages/theano/gof/opt.py", line 251, in apply
    sub_prof = optimizer.optimize(fgraph)
AttributeError: 'EquilibriumDB' object has no attribute 'optimize'

ERROR (theano.gof.opt): SeqOptimizer apply <theano.gof.opt.EquilibriumOptimizer object at 0x12706a710>
ERROR (theano.gof.opt): Traceback:
ERROR (theano.gof.opt): Traceback (most recent call last):
  File "/Volumes/Transcend/opt/anaconda3/envs/theano/lib/python2.7/site-packages/theano/gof/opt.py", line 251, in apply
    sub_prof = optimizer.optimize(fgraph)
  File "/Volumes/Transcend/opt/anaconda3/envs/theano/lib/python2.7/site-packages/theano/gof/opt.py", line 93, in optimize
    self.add_requirements(fgraph)
  File "/Volumes/Transcend/opt/anaconda3/envs/theano/lib/python2.7/site-packages/theano/gof/opt.py", line 2388, in add_requirements
    opt.add_requirements(fgraph)
AttributeError: 'SequenceDB' object has no attribute 'add_requirements'

ERROR (theano.gof.opt): SeqOptimizer apply <theano.gof.optdb.TopoDB object at 0x114e12550>
ERROR (theano.gof.opt): Traceback:
ERROR (theano.gof.opt): Traceback (most recent call last):
  File "/Volumes/Transcend/opt/anaconda3/envs/theano/lib/python2.7/site-packages/theano/gof/opt.py", line 251, in apply
    sub_prof = optimizer.optimize(fgraph)
AttributeError: 'TopoDB' object has no attribute 'optimize'

ERROR (theano.gof.opt): SeqOptimizer apply <theano.gof.optdb.EquilibriumDB object at 0x114e12690>
ERROR (theano.gof.opt): Traceback:
ERROR (theano.gof.opt): Traceback (most recent call last):
  File "/Volumes/Transcend/opt/anaconda3/envs/theano/lib/python2.7/site-packages/theano/gof/opt.py", line 251, in apply
    sub_prof = optimizer.optimize(fgraph)
AttributeError: 'EquilibriumDB' object has no attribute 'optimize'

ERROR (theano.gof.opt): SeqOptimizer apply <theano.gof.optdb.EquilibriumDB object at 0x114e12a50>
ERROR (theano.gof.opt): Traceback:
ERROR (theano.gof.opt): Traceback (most recent call last):
  File "/Volumes/Transcend/opt/anaconda3/envs/theano/lib/python2.7/site-packages/theano/gof/opt.py", line 251, in apply
    sub_prof = optimizer.optimize(fgraph)
AttributeError: 'EquilibriumDB' object has no attribute 'optimize'

ERROR (theano.gof.opt): SeqOptimizer apply <theano.gof.optdb.EquilibriumDB object at 0x126618510>
ERROR (theano.gof.opt): Traceback:
ERROR (theano.gof.opt): Traceback (most recent call last):
  File "/Volumes/Transcend/opt/anaconda3/envs/theano/lib/python2.7/site-packages/theano/gof/opt.py", line 251, in apply
    sub_prof = optimizer.optimize(fgraph)
AttributeError: 'EquilibriumDB' object has no attribute 'optimize'

ERROR (theano.gof.opt): SeqOptimizer apply SequenceDB (id 4783785552)
  position [('local_dot_to_dot22', 0), ('gemm_optimizer', 10), ('local_dot22_to_dot22scalar', 11), ('local_gemm_to_gemv', 15), ('use_c_blas', 20), ('scipy_blas', 100)]
  names set(['gemm_optimizer', 'local_gemm_to_gemv', 'local_dot_to_dot22', 'scipy_blas', 'use_c_blas', 'local_dot22_to_dot22scalar'])
  db DefaultOrderedDict([('local_dot_to_dot22', OrderedSet([<theano.gof.opt.TopoOptimizer object at 0x11d22ce10>])), ('TopoOptimizer', OrderedSet([<theano.gof.opt.TopoOptimizer object at 0x11d22ce10>, <theano.gof.opt.TopoOptimizer object at 0x126199610>, <theano.gof.opt.TopoOptimizer object at 0x126199890>, <theano.gof.opt.TopoOptimizer object at 0x1261aa790>])), ('fast_run', OrderedSet([<theano.gof.opt.TopoOptimizer object at 0x11d22ce10>, <theano.tensor.blas.GemmOptimizer object at 0x11d22ce50>, <theano.gof.opt.EquilibriumOptimizer object at 0x1261990d0>, <theano.gof.opt.TopoOptimizer object at 0x126199610>, <theano.gof.opt.TopoOptimizer object at 0x126199890>, <theano.gof.opt.TopoOptimizer object at 0x1261aa790>])), ('fast_compile', OrderedSet([<theano.gof.opt.TopoOptimizer object at 0x11d22ce10>])), ('BlasOpt', OrderedSet([<theano.gof.opt.TopoOptimizer object at 0x11d22ce10>, <theano.tensor.blas.GemmOptimizer object at 0x11d22ce50>, <theano.gof.opt.EquilibriumOptimizer object at 0x1261990d0>, <theano.gof.opt.TopoOptimizer object at 0x126199610>, <theano.gof.opt.TopoOptimizer object at 0x126199890>, <theano.gof.opt.TopoOptimizer object at 0x1261aa790>])), ('gemm_optimizer', OrderedSet([<theano.tensor.blas.GemmOptimizer object at 0x11d22ce50>])), ('GemmOptimizer', OrderedSet([<theano.tensor.blas.GemmOptimizer object at 0x11d22ce50>])), ('local_gemm_to_gemv', OrderedSet([<theano.gof.opt.EquilibriumOptimizer object at 0x1261990d0>])), ('EquilibriumOptimizer', OrderedSet([<theano.gof.opt.EquilibriumOptimizer object at 0x1261990d0>])), ('local_dot22_to_dot22scalar', OrderedSet([<theano.gof.opt.TopoOptimizer object at 0x126199610>])), ('scipy_blas', OrderedSet([<theano.gof.opt.TopoOptimizer object at 0x126199890>])), ('use_c_blas', OrderedSet([<theano.gof.opt.TopoOptimizer object at 0x1261aa790>])), ('c_blas', OrderedSet([<theano.gof.opt.TopoOptimizer object at 0x1261aa790>]))])

ERROR (theano.gof.opt): Traceback:
ERROR (theano.gof.opt): Traceback (most recent call last):
  File "/Volumes/Transcend/opt/anaconda3/envs/theano/lib/python2.7/site-packages/theano/gof/opt.py", line 251, in apply
    sub_prof = optimizer.optimize(fgraph)
AttributeError: 'SequenceDB' object has no attribute 'optimize'

ERROR (theano.gof.opt): SeqOptimizer apply <theano.gof.optdb.EquilibriumDB object at 0x114e12b50>
ERROR (theano.gof.opt): Traceback:
ERROR (theano.gof.opt): Traceback (most recent call last):
  File "/Volumes/Transcend/opt/anaconda3/envs/theano/lib/python2.7/site-packages/theano/gof/opt.py", line 251, in apply
    sub_prof = optimizer.optimize(fgraph)
AttributeError: 'EquilibriumDB' object has no attribute 'optimize'

ERROR (theano.gof.opt): SeqOptimizer apply <theano.gof.optdb.EquilibriumDB object at 0x114e12bd0>
ERROR (theano.gof.opt): Traceback:
ERROR (theano.gof.opt): Traceback (most recent call last):
  File "/Volumes/Transcend/opt/anaconda3/envs/theano/lib/python2.7/site-packages/theano/gof/opt.py", line 251, in apply
    sub_prof = optimizer.optimize(fgraph)
AttributeError: 'EquilibriumDB' object has no attribute 'optimize'

ERROR (theano.gof.opt): SeqOptimizer apply <theano.gof.optdb.EquilibriumDB object at 0x114e12c90>
ERROR (theano.gof.opt): Traceback:
ERROR (theano.gof.opt): Traceback (most recent call last):
  File "/Volumes/Transcend/opt/anaconda3/envs/theano/lib/python2.7/site-packages/theano/gof/opt.py", line 251, in apply
    sub_prof = optimizer.optimize(fgraph)
AttributeError: 'EquilibriumDB' object has no attribute 'optimize'

ERROR (theano.gof.opt): SeqOptimizer apply <theano.gof.opt.EquilibriumOptimizer object at 0x12706a590>
ERROR (theano.gof.opt): Traceback:
ERROR (theano.gof.opt): Traceback (most recent call last):
  File "/Volumes/Transcend/opt/anaconda3/envs/theano/lib/python2.7/site-packages/theano/gof/opt.py", line 251, in apply
    sub_prof = optimizer.optimize(fgraph)
  File "/Volumes/Transcend/opt/anaconda3/envs/theano/lib/python2.7/site-packages/theano/gof/opt.py", line 93, in optimize
    self.add_requirements(fgraph)
  File "/Volumes/Transcend/opt/anaconda3/envs/theano/lib/python2.7/site-packages/theano/gof/opt.py", line 2388, in add_requirements
    opt.add_requirements(fgraph)
AttributeError: 'LocalGroupDB' object has no attribute 'add_requirements'

ERROR (theano.gof.opt): SeqOptimizer apply SequenceDB (id 4783573072)
  position [('local_add_mul_fusion', 0), ('composite_elemwise_fusion', 1)]
  names set(['local_add_mul_fusion', 'composite_elemwise_fusion'])
  db DefaultOrderedDict([('local_add_mul_fusion', OrderedSet([<theano.tensor.opt.FusionOptimizer object at 0x11d1f8890>])), ('FusionOptimizer', OrderedSet([<theano.tensor.opt.FusionOptimizer object at 0x11d1f8890>, <theano.tensor.opt.FusionOptimizer object at 0x11d1f8950>])), ('fast_run', OrderedSet([<theano.tensor.opt.FusionOptimizer object at 0x11d1f8890>, <theano.tensor.opt.FusionOptimizer object at 0x11d1f8950>])), ('fusion', OrderedSet([<theano.tensor.opt.FusionOptimizer object at 0x11d1f8890>, <theano.tensor.opt.FusionOptimizer object at 0x11d1f8950>])), ('composite_elemwise_fusion', OrderedSet([<theano.tensor.opt.FusionOptimizer object at 0x11d1f8950>]))])

ERROR (theano.gof.opt): Traceback:
ERROR (theano.gof.opt): Traceback (most recent call last):
  File "/Volumes/Transcend/opt/anaconda3/envs/theano/lib/python2.7/site-packages/theano/gof/opt.py", line 251, in apply
    sub_prof = optimizer.optimize(fgraph)
AttributeError: 'SequenceDB' object has no attribute 'optimize'

ERROR (theano.gof.opt): SeqOptimizer apply <theano.gof.optdb.EquilibriumDB object at 0x12660c410>
ERROR (theano.gof.opt): Traceback:
ERROR (theano.gof.opt): Traceback (most recent call last):
  File "/Volumes/Transcend/opt/anaconda3/envs/theano/lib/python2.7/site-packages/theano/gof/opt.py", line 251, in apply
    sub_prof = optimizer.optimize(fgraph)
AttributeError: 'EquilibriumDB' object has no attribute 'optimize'

ERROR (theano.gof.opt): SeqOptimizer apply <theano.gof.opt.EquilibriumOptimizer object at 0x12706a550>
ERROR (theano.gof.opt): Traceback:
ERROR (theano.gof.opt): Traceback (most recent call last):
  File "/Volumes/Transcend/opt/anaconda3/envs/theano/lib/python2.7/site-packages/theano/gof/opt.py", line 251, in apply
    sub_prof = optimizer.optimize(fgraph)
  File "/Volumes/Transcend/opt/anaconda3/envs/theano/lib/python2.7/site-packages/theano/gof/opt.py", line 93, in optimize
    self.add_requirements(fgraph)
  File "/Volumes/Transcend/opt/anaconda3/envs/theano/lib/python2.7/site-packages/theano/gof/opt.py", line 2388, in add_requirements
    opt.add_requirements(fgraph)
AttributeError: 'SequenceDB' object has no attribute 'add_requirements'

ERROR (theano.gof.opt): SeqOptimizer apply <theano.gof.optdb.TopoDB object at 0x114e12550>
ERROR (theano.gof.opt): Traceback:
ERROR (theano.gof.opt): Traceback (most recent call last):
  File "/Volumes/Transcend/opt/anaconda3/envs/theano/lib/python2.7/site-packages/theano/gof/opt.py", line 251, in apply
    sub_prof = optimizer.optimize(fgraph)
AttributeError: 'TopoDB' object has no attribute 'optimize'

ERROR (theano.gof.opt): SeqOptimizer apply <theano.gof.optdb.EquilibriumDB object at 0x114e12690>
ERROR (theano.gof.opt): Traceback:
ERROR (theano.gof.opt): Traceback (most recent call last):
  File "/Volumes/Transcend/opt/anaconda3/envs/theano/lib/python2.7/site-packages/theano/gof/opt.py", line 251, in apply
    sub_prof = optimizer.optimize(fgraph)
AttributeError: 'EquilibriumDB' object has no attribute 'optimize'

ERROR (theano.gof.opt): SeqOptimizer apply <theano.gof.optdb.EquilibriumDB object at 0x114e12a50>
ERROR (theano.gof.opt): Traceback:
ERROR (theano.gof.opt): Traceback (most recent call last):
  File "/Volumes/Transcend/opt/anaconda3/envs/theano/lib/python2.7/site-packages/theano/gof/opt.py", line 251, in apply
    sub_prof = optimizer.optimize(fgraph)
AttributeError: 'EquilibriumDB' object has no attribute 'optimize'

ERROR (theano.gof.opt): SeqOptimizer apply <theano.gof.optdb.EquilibriumDB object at 0x126618510>
ERROR (theano.gof.opt): Traceback:
ERROR (theano.gof.opt): Traceback (most recent call last):
  File "/Volumes/Transcend/opt/anaconda3/envs/theano/lib/python2.7/site-packages/theano/gof/opt.py", line 251, in apply
    sub_prof = optimizer.optimize(fgraph)
AttributeError: 'EquilibriumDB' object has no attribute 'optimize'

ERROR (theano.gof.opt): SeqOptimizer apply SequenceDB (id 4783785552)
  position [('local_dot_to_dot22', 0), ('gemm_optimizer', 10), ('local_dot22_to_dot22scalar', 11), ('local_gemm_to_gemv', 15), ('use_c_blas', 20), ('scipy_blas', 100)]
  names set(['gemm_optimizer', 'local_gemm_to_gemv', 'local_dot_to_dot22', 'scipy_blas', 'use_c_blas', 'local_dot22_to_dot22scalar'])
  db DefaultOrderedDict([('local_dot_to_dot22', OrderedSet([<theano.gof.opt.TopoOptimizer object at 0x11d22ce10>])), ('TopoOptimizer', OrderedSet([<theano.gof.opt.TopoOptimizer object at 0x11d22ce10>, <theano.gof.opt.TopoOptimizer object at 0x126199610>, <theano.gof.opt.TopoOptimizer object at 0x126199890>, <theano.gof.opt.TopoOptimizer object at 0x1261aa790>])), ('fast_run', OrderedSet([<theano.gof.opt.TopoOptimizer object at 0x11d22ce10>, <theano.tensor.blas.GemmOptimizer object at 0x11d22ce50>, <theano.gof.opt.EquilibriumOptimizer object at 0x1261990d0>, <theano.gof.opt.TopoOptimizer object at 0x126199610>, <theano.gof.opt.TopoOptimizer object at 0x126199890>, <theano.gof.opt.TopoOptimizer object at 0x1261aa790>])), ('fast_compile', OrderedSet([<theano.gof.opt.TopoOptimizer object at 0x11d22ce10>])), ('BlasOpt', OrderedSet([<theano.gof.opt.TopoOptimizer object at 0x11d22ce10>, <theano.tensor.blas.GemmOptimizer object at 0x11d22ce50>, <theano.gof.opt.EquilibriumOptimizer object at 0x1261990d0>, <theano.gof.opt.TopoOptimizer object at 0x126199610>, <theano.gof.opt.TopoOptimizer object at 0x126199890>, <theano.gof.opt.TopoOptimizer object at 0x1261aa790>])), ('gemm_optimizer', OrderedSet([<theano.tensor.blas.GemmOptimizer object at 0x11d22ce50>])), ('GemmOptimizer', OrderedSet([<theano.tensor.blas.GemmOptimizer object at 0x11d22ce50>])), ('local_gemm_to_gemv', OrderedSet([<theano.gof.opt.EquilibriumOptimizer object at 0x1261990d0>])), ('EquilibriumOptimizer', OrderedSet([<theano.gof.opt.EquilibriumOptimizer object at 0x1261990d0>])), ('local_dot22_to_dot22scalar', OrderedSet([<theano.gof.opt.TopoOptimizer object at 0x126199610>])), ('scipy_blas', OrderedSet([<theano.gof.opt.TopoOptimizer object at 0x126199890>])), ('use_c_blas', OrderedSet([<theano.gof.opt.TopoOptimizer object at 0x1261aa790>])), ('c_blas', OrderedSet([<theano.gof.opt.TopoOptimizer object at 0x1261aa790>]))])

ERROR (theano.gof.opt): Traceback:
ERROR (theano.gof.opt): Traceback (most recent call last):
  File "/Volumes/Transcend/opt/anaconda3/envs/theano/lib/python2.7/site-packages/theano/gof/opt.py", line 251, in apply
    sub_prof = optimizer.optimize(fgraph)
AttributeError: 'SequenceDB' object has no attribute 'optimize'

ERROR (theano.gof.opt): SeqOptimizer apply <theano.gof.optdb.EquilibriumDB object at 0x114e12b50>
ERROR (theano.gof.opt): Traceback:
ERROR (theano.gof.opt): Traceback (most recent call last):
  File "/Volumes/Transcend/opt/anaconda3/envs/theano/lib/python2.7/site-packages/theano/gof/opt.py", line 251, in apply
    sub_prof = optimizer.optimize(fgraph)
AttributeError: 'EquilibriumDB' object has no attribute 'optimize'

ERROR (theano.gof.opt): SeqOptimizer apply <theano.gof.optdb.EquilibriumDB object at 0x114e12bd0>
ERROR (theano.gof.opt): Traceback:
ERROR (theano.gof.opt): Traceback (most recent call last):
  File "/Volumes/Transcend/opt/anaconda3/envs/theano/lib/python2.7/site-packages/theano/gof/opt.py", line 251, in apply
    sub_prof = optimizer.optimize(fgraph)
AttributeError: 'EquilibriumDB' object has no attribute 'optimize'

ERROR (theano.gof.opt): SeqOptimizer apply <theano.gof.optdb.EquilibriumDB object at 0x114e12c90>
ERROR (theano.gof.opt): Traceback:
ERROR (theano.gof.opt): Traceback (most recent call last):
  File "/Volumes/Transcend/opt/anaconda3/envs/theano/lib/python2.7/site-packages/theano/gof/opt.py", line 251, in apply
    sub_prof = optimizer.optimize(fgraph)
AttributeError: 'EquilibriumDB' object has no attribute 'optimize'

ERROR (theano.gof.opt): SeqOptimizer apply <theano.gof.opt.EquilibriumOptimizer object at 0x1278bc050>
ERROR (theano.gof.opt): Traceback:
ERROR (theano.gof.opt): Traceback (most recent call last):
  File "/Volumes/Transcend/opt/anaconda3/envs/theano/lib/python2.7/site-packages/theano/gof/opt.py", line 251, in apply
    sub_prof = optimizer.optimize(fgraph)
  File "/Volumes/Transcend/opt/anaconda3/envs/theano/lib/python2.7/site-packages/theano/gof/opt.py", line 93, in optimize
    self.add_requirements(fgraph)
  File "/Volumes/Transcend/opt/anaconda3/envs/theano/lib/python2.7/site-packages/theano/gof/opt.py", line 2388, in add_requirements
    opt.add_requirements(fgraph)
AttributeError: 'LocalGroupDB' object has no attribute 'add_requirements'

ERROR (theano.gof.opt): SeqOptimizer apply SequenceDB (id 4783573072)
  position [('local_add_mul_fusion', 0), ('composite_elemwise_fusion', 1)]
  names set(['local_add_mul_fusion', 'composite_elemwise_fusion'])
  db DefaultOrderedDict([('local_add_mul_fusion', OrderedSet([<theano.tensor.opt.FusionOptimizer object at 0x11d1f8890>])), ('FusionOptimizer', OrderedSet([<theano.tensor.opt.FusionOptimizer object at 0x11d1f8890>, <theano.tensor.opt.FusionOptimizer object at 0x11d1f8950>])), ('fast_run', OrderedSet([<theano.tensor.opt.FusionOptimizer object at 0x11d1f8890>, <theano.tensor.opt.FusionOptimizer object at 0x11d1f8950>])), ('fusion', OrderedSet([<theano.tensor.opt.FusionOptimizer object at 0x11d1f8890>, <theano.tensor.opt.FusionOptimizer object at 0x11d1f8950>])), ('composite_elemwise_fusion', OrderedSet([<theano.tensor.opt.FusionOptimizer object at 0x11d1f8950>]))])

ERROR (theano.gof.opt): Traceback:
ERROR (theano.gof.opt): Traceback (most recent call last):
  File "/Volumes/Transcend/opt/anaconda3/envs/theano/lib/python2.7/site-packages/theano/gof/opt.py", line 251, in apply
    sub_prof = optimizer.optimize(fgraph)
AttributeError: 'SequenceDB' object has no attribute 'optimize'

ERROR (theano.gof.opt): SeqOptimizer apply <theano.gof.optdb.EquilibriumDB object at 0x12660c410>
ERROR (theano.gof.opt): Traceback:
ERROR (theano.gof.opt): Traceback (most recent call last):
  File "/Volumes/Transcend/opt/anaconda3/envs/theano/lib/python2.7/site-packages/theano/gof/opt.py", line 251, in apply
    sub_prof = optimizer.optimize(fgraph)
AttributeError: 'EquilibriumDB' object has no attribute 'optimize'

ERROR (theano.gof.opt): SeqOptimizer apply <theano.gof.opt.EquilibriumOptimizer object at 0x128e69250>
ERROR (theano.gof.opt): Traceback:
ERROR (theano.gof.opt): Traceback (most recent call last):
  File "/Volumes/Transcend/opt/anaconda3/envs/theano/lib/python2.7/site-packages/theano/gof/opt.py", line 251, in apply
    sub_prof = optimizer.optimize(fgraph)
  File "/Volumes/Transcend/opt/anaconda3/envs/theano/lib/python2.7/site-packages/theano/gof/opt.py", line 93, in optimize
    self.add_requirements(fgraph)
  File "/Volumes/Transcend/opt/anaconda3/envs/theano/lib/python2.7/site-packages/theano/gof/opt.py", line 2388, in add_requirements
    opt.add_requirements(fgraph)
AttributeError: 'SequenceDB' object has no attribute 'add_requirements'

ERROR (theano.gof.opt): SeqOptimizer apply <theano.gof.optdb.TopoDB object at 0x114e12550>
ERROR (theano.gof.opt): Traceback:
ERROR (theano.gof.opt): Traceback (most recent call last):
  File "/Volumes/Transcend/opt/anaconda3/envs/theano/lib/python2.7/site-packages/theano/gof/opt.py", line 251, in apply
    sub_prof = optimizer.optimize(fgraph)
AttributeError: 'TopoDB' object has no attribute 'optimize'

ERROR (theano.gof.opt): SeqOptimizer apply <theano.gof.optdb.EquilibriumDB object at 0x114e12690>
ERROR (theano.gof.opt): Traceback:
ERROR (theano.gof.opt): Traceback (most recent call last):
  File "/Volumes/Transcend/opt/anaconda3/envs/theano/lib/python2.7/site-packages/theano/gof/opt.py", line 251, in apply
    sub_prof = optimizer.optimize(fgraph)
AttributeError: 'EquilibriumDB' object has no attribute 'optimize'

ERROR (theano.gof.opt): SeqOptimizer apply <theano.gof.optdb.EquilibriumDB object at 0x114e12a50>
ERROR (theano.gof.opt): Traceback:
ERROR (theano.gof.opt): Traceback (most recent call last):
  File "/Volumes/Transcend/opt/anaconda3/envs/theano/lib/python2.7/site-packages/theano/gof/opt.py", line 251, in apply
    sub_prof = optimizer.optimize(fgraph)
AttributeError: 'EquilibriumDB' object has no attribute 'optimize'

ERROR (theano.gof.opt): SeqOptimizer apply <theano.gof.optdb.EquilibriumDB object at 0x126618510>
ERROR (theano.gof.opt): Traceback:
ERROR (theano.gof.opt): Traceback (most recent call last):
  File "/Volumes/Transcend/opt/anaconda3/envs/theano/lib/python2.7/site-packages/theano/gof/opt.py", line 251, in apply
    sub_prof = optimizer.optimize(fgraph)
AttributeError: 'EquilibriumDB' object has no attribute 'optimize'

ERROR (theano.gof.opt): SeqOptimizer apply SequenceDB (id 4783785552)
  position [('local_dot_to_dot22', 0), ('gemm_optimizer', 10), ('local_dot22_to_dot22scalar', 11), ('local_gemm_to_gemv', 15), ('use_c_blas', 20), ('scipy_blas', 100)]
  names set(['gemm_optimizer', 'local_gemm_to_gemv', 'local_dot_to_dot22', 'scipy_blas', 'use_c_blas', 'local_dot22_to_dot22scalar'])
  db DefaultOrderedDict([('local_dot_to_dot22', OrderedSet([<theano.gof.opt.TopoOptimizer object at 0x11d22ce10>])), ('TopoOptimizer', OrderedSet([<theano.gof.opt.TopoOptimizer object at 0x11d22ce10>, <theano.gof.opt.TopoOptimizer object at 0x126199610>, <theano.gof.opt.TopoOptimizer object at 0x126199890>, <theano.gof.opt.TopoOptimizer object at 0x1261aa790>])), ('fast_run', OrderedSet([<theano.gof.opt.TopoOptimizer object at 0x11d22ce10>, <theano.tensor.blas.GemmOptimizer object at 0x11d22ce50>, <theano.gof.opt.EquilibriumOptimizer object at 0x1261990d0>, <theano.gof.opt.TopoOptimizer object at 0x126199610>, <theano.gof.opt.TopoOptimizer object at 0x126199890>, <theano.gof.opt.TopoOptimizer object at 0x1261aa790>])), ('fast_compile', OrderedSet([<theano.gof.opt.TopoOptimizer object at 0x11d22ce10>])), ('BlasOpt', OrderedSet([<theano.gof.opt.TopoOptimizer object at 0x11d22ce10>, <theano.tensor.blas.GemmOptimizer object at 0x11d22ce50>, <theano.gof.opt.EquilibriumOptimizer object at 0x1261990d0>, <theano.gof.opt.TopoOptimizer object at 0x126199610>, <theano.gof.opt.TopoOptimizer object at 0x126199890>, <theano.gof.opt.TopoOptimizer object at 0x1261aa790>])), ('gemm_optimizer', OrderedSet([<theano.tensor.blas.GemmOptimizer object at 0x11d22ce50>])), ('GemmOptimizer', OrderedSet([<theano.tensor.blas.GemmOptimizer object at 0x11d22ce50>])), ('local_gemm_to_gemv', OrderedSet([<theano.gof.opt.EquilibriumOptimizer object at 0x1261990d0>])), ('EquilibriumOptimizer', OrderedSet([<theano.gof.opt.EquilibriumOptimizer object at 0x1261990d0>])), ('local_dot22_to_dot22scalar', OrderedSet([<theano.gof.opt.TopoOptimizer object at 0x126199610>])), ('scipy_blas', OrderedSet([<theano.gof.opt.TopoOptimizer object at 0x126199890>])), ('use_c_blas', OrderedSet([<theano.gof.opt.TopoOptimizer object at 0x1261aa790>])), ('c_blas', OrderedSet([<theano.gof.opt.TopoOptimizer object at 0x1261aa790>]))])

ERROR (theano.gof.opt): Traceback:
ERROR (theano.gof.opt): Traceback (most recent call last):
  File "/Volumes/Transcend/opt/anaconda3/envs/theano/lib/python2.7/site-packages/theano/gof/opt.py", line 251, in apply
    sub_prof = optimizer.optimize(fgraph)
AttributeError: 'SequenceDB' object has no attribute 'optimize'

ERROR (theano.gof.opt): SeqOptimizer apply <theano.gof.optdb.EquilibriumDB object at 0x114e12b50>
ERROR (theano.gof.opt): Traceback:
ERROR (theano.gof.opt): Traceback (most recent call last):
  File "/Volumes/Transcend/opt/anaconda3/envs/theano/lib/python2.7/site-packages/theano/gof/opt.py", line 251, in apply
    sub_prof = optimizer.optimize(fgraph)
AttributeError: 'EquilibriumDB' object has no attribute 'optimize'

ERROR (theano.gof.opt): SeqOptimizer apply <theano.gof.optdb.EquilibriumDB object at 0x114e12bd0>
ERROR (theano.gof.opt): Traceback:
ERROR (theano.gof.opt): Traceback (most recent call last):
  File "/Volumes/Transcend/opt/anaconda3/envs/theano/lib/python2.7/site-packages/theano/gof/opt.py", line 251, in apply
    sub_prof = optimizer.optimize(fgraph)
AttributeError: 'EquilibriumDB' object has no attribute 'optimize'

ERROR (theano.gof.opt): SeqOptimizer apply <theano.gof.optdb.EquilibriumDB object at 0x114e12c90>
ERROR (theano.gof.opt): Traceback:
ERROR (theano.gof.opt): Traceback (most recent call last):
  File "/Volumes/Transcend/opt/anaconda3/envs/theano/lib/python2.7/site-packages/theano/gof/opt.py", line 251, in apply
    sub_prof = optimizer.optimize(fgraph)
AttributeError: 'EquilibriumDB' object has no attribute 'optimize'

ERROR (theano.gof.opt): SeqOptimizer apply <theano.gof.opt.EquilibriumOptimizer object at 0x128e69510>
ERROR (theano.gof.opt): Traceback:
ERROR (theano.gof.opt): Traceback (most recent call last):
  File "/Volumes/Transcend/opt/anaconda3/envs/theano/lib/python2.7/site-packages/theano/gof/opt.py", line 251, in apply
    sub_prof = optimizer.optimize(fgraph)
  File "/Volumes/Transcend/opt/anaconda3/envs/theano/lib/python2.7/site-packages/theano/gof/opt.py", line 93, in optimize
    self.add_requirements(fgraph)
  File "/Volumes/Transcend/opt/anaconda3/envs/theano/lib/python2.7/site-packages/theano/gof/opt.py", line 2388, in add_requirements
    opt.add_requirements(fgraph)
AttributeError: 'LocalGroupDB' object has no attribute 'add_requirements'

ERROR (theano.gof.opt): SeqOptimizer apply SequenceDB (id 4783573072)
  position [('local_add_mul_fusion', 0), ('composite_elemwise_fusion', 1)]
  names set(['local_add_mul_fusion', 'composite_elemwise_fusion'])
  db DefaultOrderedDict([('local_add_mul_fusion', OrderedSet([<theano.tensor.opt.FusionOptimizer object at 0x11d1f8890>])), ('FusionOptimizer', OrderedSet([<theano.tensor.opt.FusionOptimizer object at 0x11d1f8890>, <theano.tensor.opt.FusionOptimizer object at 0x11d1f8950>])), ('fast_run', OrderedSet([<theano.tensor.opt.FusionOptimizer object at 0x11d1f8890>, <theano.tensor.opt.FusionOptimizer object at 0x11d1f8950>])), ('fusion', OrderedSet([<theano.tensor.opt.FusionOptimizer object at 0x11d1f8890>, <theano.tensor.opt.FusionOptimizer object at 0x11d1f8950>])), ('composite_elemwise_fusion', OrderedSet([<theano.tensor.opt.FusionOptimizer object at 0x11d1f8950>]))])

ERROR (theano.gof.opt): Traceback:
ERROR (theano.gof.opt): Traceback (most recent call last):
  File "/Volumes/Transcend/opt/anaconda3/envs/theano/lib/python2.7/site-packages/theano/gof/opt.py", line 251, in apply
    sub_prof = optimizer.optimize(fgraph)
AttributeError: 'SequenceDB' object has no attribute 'optimize'

ERROR (theano.gof.opt): SeqOptimizer apply <theano.gof.optdb.EquilibriumDB object at 0x12660c410>
ERROR (theano.gof.opt): Traceback:
ERROR (theano.gof.opt): Traceback (most recent call last):
  File "/Volumes/Transcend/opt/anaconda3/envs/theano/lib/python2.7/site-packages/theano/gof/opt.py", line 251, in apply
    sub_prof = optimizer.optimize(fgraph)
AttributeError: 'EquilibriumDB' object has no attribute 'optimize'

ERROR (theano.gof.opt): SeqOptimizer apply <theano.gof.opt.EquilibriumOptimizer object at 0x126ea92d0>
ERROR (theano.gof.opt): Traceback:
ERROR (theano.gof.opt): Traceback (most recent call last):
  File "/Volumes/Transcend/opt/anaconda3/envs/theano/lib/python2.7/site-packages/theano/gof/opt.py", line 251, in apply
    sub_prof = optimizer.optimize(fgraph)
  File "/Volumes/Transcend/opt/anaconda3/envs/theano/lib/python2.7/site-packages/theano/gof/opt.py", line 93, in optimize
    self.add_requirements(fgraph)
  File "/Volumes/Transcend/opt/anaconda3/envs/theano/lib/python2.7/site-packages/theano/gof/opt.py", line 2388, in add_requirements
    opt.add_requirements(fgraph)
AttributeError: 'SequenceDB' object has no attribute 'add_requirements'

ERROR (theano.gof.opt): SeqOptimizer apply <theano.gof.optdb.TopoDB object at 0x114e12550>
ERROR (theano.gof.opt): Traceback:
ERROR (theano.gof.opt): Traceback (most recent call last):
  File "/Volumes/Transcend/opt/anaconda3/envs/theano/lib/python2.7/site-packages/theano/gof/opt.py", line 251, in apply
    sub_prof = optimizer.optimize(fgraph)
AttributeError: 'TopoDB' object has no attribute 'optimize'

ERROR (theano.gof.opt): SeqOptimizer apply <theano.gof.optdb.EquilibriumDB object at 0x114e12690>
ERROR (theano.gof.opt): Traceback:
ERROR (theano.gof.opt): Traceback (most recent call last):
  File "/Volumes/Transcend/opt/anaconda3/envs/theano/lib/python2.7/site-packages/theano/gof/opt.py", line 251, in apply
    sub_prof = optimizer.optimize(fgraph)
AttributeError: 'EquilibriumDB' object has no attribute 'optimize'

ERROR (theano.gof.opt): SeqOptimizer apply <theano.gof.optdb.EquilibriumDB object at 0x114e12a50>
ERROR (theano.gof.opt): Traceback:
ERROR (theano.gof.opt): Traceback (most recent call last):
  File "/Volumes/Transcend/opt/anaconda3/envs/theano/lib/python2.7/site-packages/theano/gof/opt.py", line 251, in apply
    sub_prof = optimizer.optimize(fgraph)
AttributeError: 'EquilibriumDB' object has no attribute 'optimize'

ERROR (theano.gof.opt): SeqOptimizer apply <theano.gof.optdb.EquilibriumDB object at 0x126618510>
ERROR (theano.gof.opt): Traceback:
ERROR (theano.gof.opt): Traceback (most recent call last):
  File "/Volumes/Transcend/opt/anaconda3/envs/theano/lib/python2.7/site-packages/theano/gof/opt.py", line 251, in apply
    sub_prof = optimizer.optimize(fgraph)
AttributeError: 'EquilibriumDB' object has no attribute 'optimize'

ERROR (theano.gof.opt): SeqOptimizer apply SequenceDB (id 4783785552)
  position [('local_dot_to_dot22', 0), ('gemm_optimizer', 10), ('local_dot22_to_dot22scalar', 11), ('local_gemm_to_gemv', 15), ('use_c_blas', 20), ('scipy_blas', 100)]
  names set(['gemm_optimizer', 'local_gemm_to_gemv', 'local_dot_to_dot22', 'scipy_blas', 'use_c_blas', 'local_dot22_to_dot22scalar'])
  db DefaultOrderedDict([('local_dot_to_dot22', OrderedSet([<theano.gof.opt.TopoOptimizer object at 0x11d22ce10>])), ('TopoOptimizer', OrderedSet([<theano.gof.opt.TopoOptimizer object at 0x11d22ce10>, <theano.gof.opt.TopoOptimizer object at 0x126199610>, <theano.gof.opt.TopoOptimizer object at 0x126199890>, <theano.gof.opt.TopoOptimizer object at 0x1261aa790>])), ('fast_run', OrderedSet([<theano.gof.opt.TopoOptimizer object at 0x11d22ce10>, <theano.tensor.blas.GemmOptimizer object at 0x11d22ce50>, <theano.gof.opt.EquilibriumOptimizer object at 0x1261990d0>, <theano.gof.opt.TopoOptimizer object at 0x126199610>, <theano.gof.opt.TopoOptimizer object at 0x126199890>, <theano.gof.opt.TopoOptimizer object at 0x1261aa790>])), ('fast_compile', OrderedSet([<theano.gof.opt.TopoOptimizer object at 0x11d22ce10>])), ('BlasOpt', OrderedSet([<theano.gof.opt.TopoOptimizer object at 0x11d22ce10>, <theano.tensor.blas.GemmOptimizer object at 0x11d22ce50>, <theano.gof.opt.EquilibriumOptimizer object at 0x1261990d0>, <theano.gof.opt.TopoOptimizer object at 0x126199610>, <theano.gof.opt.TopoOptimizer object at 0x126199890>, <theano.gof.opt.TopoOptimizer object at 0x1261aa790>])), ('gemm_optimizer', OrderedSet([<theano.tensor.blas.GemmOptimizer object at 0x11d22ce50>])), ('GemmOptimizer', OrderedSet([<theano.tensor.blas.GemmOptimizer object at 0x11d22ce50>])), ('local_gemm_to_gemv', OrderedSet([<theano.gof.opt.EquilibriumOptimizer object at 0x1261990d0>])), ('EquilibriumOptimizer', OrderedSet([<theano.gof.opt.EquilibriumOptimizer object at 0x1261990d0>])), ('local_dot22_to_dot22scalar', OrderedSet([<theano.gof.opt.TopoOptimizer object at 0x126199610>])), ('scipy_blas', OrderedSet([<theano.gof.opt.TopoOptimizer object at 0x126199890>])), ('use_c_blas', OrderedSet([<theano.gof.opt.TopoOptimizer object at 0x1261aa790>])), ('c_blas', OrderedSet([<theano.gof.opt.TopoOptimizer object at 0x1261aa790>]))])

ERROR (theano.gof.opt): Traceback:
ERROR (theano.gof.opt): Traceback (most recent call last):
  File "/Volumes/Transcend/opt/anaconda3/envs/theano/lib/python2.7/site-packages/theano/gof/opt.py", line 251, in apply
    sub_prof = optimizer.optimize(fgraph)
AttributeError: 'SequenceDB' object has no attribute 'optimize'

ERROR (theano.gof.opt): SeqOptimizer apply <theano.gof.optdb.EquilibriumDB object at 0x114e12b50>
ERROR (theano.gof.opt): Traceback:
ERROR (theano.gof.opt): Traceback (most recent call last):
  File "/Volumes/Transcend/opt/anaconda3/envs/theano/lib/python2.7/site-packages/theano/gof/opt.py", line 251, in apply
    sub_prof = optimizer.optimize(fgraph)
AttributeError: 'EquilibriumDB' object has no attribute 'optimize'

ERROR (theano.gof.opt): SeqOptimizer apply <theano.gof.optdb.EquilibriumDB object at 0x114e12bd0>
ERROR (theano.gof.opt): Traceback:
ERROR (theano.gof.opt): Traceback (most recent call last):
  File "/Volumes/Transcend/opt/anaconda3/envs/theano/lib/python2.7/site-packages/theano/gof/opt.py", line 251, in apply
    sub_prof = optimizer.optimize(fgraph)
AttributeError: 'EquilibriumDB' object has no attribute 'optimize'

ERROR (theano.gof.opt): SeqOptimizer apply <theano.gof.optdb.EquilibriumDB object at 0x114e12c90>
ERROR (theano.gof.opt): Traceback:
ERROR (theano.gof.opt): Traceback (most recent call last):
  File "/Volumes/Transcend/opt/anaconda3/envs/theano/lib/python2.7/site-packages/theano/gof/opt.py", line 251, in apply
    sub_prof = optimizer.optimize(fgraph)
AttributeError: 'EquilibriumDB' object has no attribute 'optimize'

ERROR (theano.gof.opt): SeqOptimizer apply <theano.gof.opt.EquilibriumOptimizer object at 0x126ea9550>
ERROR (theano.gof.opt): Traceback:
ERROR (theano.gof.opt): Traceback (most recent call last):
  File "/Volumes/Transcend/opt/anaconda3/envs/theano/lib/python2.7/site-packages/theano/gof/opt.py", line 251, in apply
    sub_prof = optimizer.optimize(fgraph)
  File "/Volumes/Transcend/opt/anaconda3/envs/theano/lib/python2.7/site-packages/theano/gof/opt.py", line 93, in optimize
    self.add_requirements(fgraph)
  File "/Volumes/Transcend/opt/anaconda3/envs/theano/lib/python2.7/site-packages/theano/gof/opt.py", line 2388, in add_requirements
    opt.add_requirements(fgraph)
AttributeError: 'LocalGroupDB' object has no attribute 'add_requirements'

ERROR (theano.gof.opt): SeqOptimizer apply SequenceDB (id 4783573072)
  position [('local_add_mul_fusion', 0), ('composite_elemwise_fusion', 1)]
  names set(['local_add_mul_fusion', 'composite_elemwise_fusion'])
  db DefaultOrderedDict([('local_add_mul_fusion', OrderedSet([<theano.tensor.opt.FusionOptimizer object at 0x11d1f8890>])), ('FusionOptimizer', OrderedSet([<theano.tensor.opt.FusionOptimizer object at 0x11d1f8890>, <theano.tensor.opt.FusionOptimizer object at 0x11d1f8950>])), ('fast_run', OrderedSet([<theano.tensor.opt.FusionOptimizer object at 0x11d1f8890>, <theano.tensor.opt.FusionOptimizer object at 0x11d1f8950>])), ('fusion', OrderedSet([<theano.tensor.opt.FusionOptimizer object at 0x11d1f8890>, <theano.tensor.opt.FusionOptimizer object at 0x11d1f8950>])), ('composite_elemwise_fusion', OrderedSet([<theano.tensor.opt.FusionOptimizer object at 0x11d1f8950>]))])

ERROR (theano.gof.opt): Traceback:
ERROR (theano.gof.opt): Traceback (most recent call last):
  File "/Volumes/Transcend/opt/anaconda3/envs/theano/lib/python2.7/site-packages/theano/gof/opt.py", line 251, in apply
    sub_prof = optimizer.optimize(fgraph)
AttributeError: 'SequenceDB' object has no attribute 'optimize'

ERROR (theano.gof.opt): SeqOptimizer apply <theano.gof.optdb.EquilibriumDB object at 0x12660c410>
ERROR (theano.gof.opt): Traceback:
ERROR (theano.gof.opt): Traceback (most recent call last):
  File "/Volumes/Transcend/opt/anaconda3/envs/theano/lib/python2.7/site-packages/theano/gof/opt.py", line 251, in apply
    sub_prof = optimizer.optimize(fgraph)
AttributeError: 'EquilibriumDB' object has no attribute 'optimize'

ERROR (theano.gof.opt): SeqOptimizer apply <theano.gof.opt.EquilibriumOptimizer object at 0x139217e10>
ERROR (theano.gof.opt): Traceback:
ERROR (theano.gof.opt): Traceback (most recent call last):
  File "/Volumes/Transcend/opt/anaconda3/envs/theano/lib/python2.7/site-packages/theano/gof/opt.py", line 251, in apply
    sub_prof = optimizer.optimize(fgraph)
  File "/Volumes/Transcend/opt/anaconda3/envs/theano/lib/python2.7/site-packages/theano/gof/opt.py", line 93, in optimize
    self.add_requirements(fgraph)
  File "/Volumes/Transcend/opt/anaconda3/envs/theano/lib/python2.7/site-packages/theano/gof/opt.py", line 2388, in add_requirements
    opt.add_requirements(fgraph)
AttributeError: 'SequenceDB' object has no attribute 'add_requirements'

ERROR (theano.gof.opt): SeqOptimizer apply <theano.gof.optdb.TopoDB object at 0x114e12550>
ERROR (theano.gof.opt): Traceback:
ERROR (theano.gof.opt): Traceback (most recent call last):
  File "/Volumes/Transcend/opt/anaconda3/envs/theano/lib/python2.7/site-packages/theano/gof/opt.py", line 251, in apply
    sub_prof = optimizer.optimize(fgraph)
AttributeError: 'TopoDB' object has no attribute 'optimize'

ERROR (theano.gof.opt): SeqOptimizer apply <theano.gof.optdb.EquilibriumDB object at 0x114e12690>
ERROR (theano.gof.opt): Traceback:
ERROR (theano.gof.opt): Traceback (most recent call last):
  File "/Volumes/Transcend/opt/anaconda3/envs/theano/lib/python2.7/site-packages/theano/gof/opt.py", line 251, in apply
    sub_prof = optimizer.optimize(fgraph)
AttributeError: 'EquilibriumDB' object has no attribute 'optimize'

ERROR (theano.gof.opt): SeqOptimizer apply <theano.gof.optdb.EquilibriumDB object at 0x114e12a50>
ERROR (theano.gof.opt): Traceback:
ERROR (theano.gof.opt): Traceback (most recent call last):
  File "/Volumes/Transcend/opt/anaconda3/envs/theano/lib/python2.7/site-packages/theano/gof/opt.py", line 251, in apply
    sub_prof = optimizer.optimize(fgraph)
AttributeError: 'EquilibriumDB' object has no attribute 'optimize'

ERROR (theano.gof.opt): SeqOptimizer apply <theano.gof.optdb.EquilibriumDB object at 0x126618510>
ERROR (theano.gof.opt): Traceback:
ERROR (theano.gof.opt): Traceback (most recent call last):
  File "/Volumes/Transcend/opt/anaconda3/envs/theano/lib/python2.7/site-packages/theano/gof/opt.py", line 251, in apply
    sub_prof = optimizer.optimize(fgraph)
AttributeError: 'EquilibriumDB' object has no attribute 'optimize'

ERROR (theano.gof.opt): SeqOptimizer apply SequenceDB (id 4783785552)
  position [('local_dot_to_dot22', 0), ('gemm_optimizer', 10), ('local_dot22_to_dot22scalar', 11), ('local_gemm_to_gemv', 15), ('use_c_blas', 20), ('scipy_blas', 100)]
  names set(['gemm_optimizer', 'local_gemm_to_gemv', 'local_dot_to_dot22', 'scipy_blas', 'use_c_blas', 'local_dot22_to_dot22scalar'])
  db DefaultOrderedDict([('local_dot_to_dot22', OrderedSet([<theano.gof.opt.TopoOptimizer object at 0x11d22ce10>])), ('TopoOptimizer', OrderedSet([<theano.gof.opt.TopoOptimizer object at 0x11d22ce10>, <theano.gof.opt.TopoOptimizer object at 0x126199610>, <theano.gof.opt.TopoOptimizer object at 0x126199890>, <theano.gof.opt.TopoOptimizer object at 0x1261aa790>])), ('fast_run', OrderedSet([<theano.gof.opt.TopoOptimizer object at 0x11d22ce10>, <theano.tensor.blas.GemmOptimizer object at 0x11d22ce50>, <theano.gof.opt.EquilibriumOptimizer object at 0x1261990d0>, <theano.gof.opt.TopoOptimizer object at 0x126199610>, <theano.gof.opt.TopoOptimizer object at 0x126199890>, <theano.gof.opt.TopoOptimizer object at 0x1261aa790>])), ('fast_compile', OrderedSet([<theano.gof.opt.TopoOptimizer object at 0x11d22ce10>])), ('BlasOpt', OrderedSet([<theano.gof.opt.TopoOptimizer object at 0x11d22ce10>, <theano.tensor.blas.GemmOptimizer object at 0x11d22ce50>, <theano.gof.opt.EquilibriumOptimizer object at 0x1261990d0>, <theano.gof.opt.TopoOptimizer object at 0x126199610>, <theano.gof.opt.TopoOptimizer object at 0x126199890>, <theano.gof.opt.TopoOptimizer object at 0x1261aa790>])), ('gemm_optimizer', OrderedSet([<theano.tensor.blas.GemmOptimizer object at 0x11d22ce50>])), ('GemmOptimizer', OrderedSet([<theano.tensor.blas.GemmOptimizer object at 0x11d22ce50>])), ('local_gemm_to_gemv', OrderedSet([<theano.gof.opt.EquilibriumOptimizer object at 0x1261990d0>])), ('EquilibriumOptimizer', OrderedSet([<theano.gof.opt.EquilibriumOptimizer object at 0x1261990d0>])), ('local_dot22_to_dot22scalar', OrderedSet([<theano.gof.opt.TopoOptimizer object at 0x126199610>])), ('scipy_blas', OrderedSet([<theano.gof.opt.TopoOptimizer object at 0x126199890>])), ('use_c_blas', OrderedSet([<theano.gof.opt.TopoOptimizer object at 0x1261aa790>])), ('c_blas', OrderedSet([<theano.gof.opt.TopoOptimizer object at 0x1261aa790>]))])

ERROR (theano.gof.opt): Traceback:
ERROR (theano.gof.opt): Traceback (most recent call last):
  File "/Volumes/Transcend/opt/anaconda3/envs/theano/lib/python2.7/site-packages/theano/gof/opt.py", line 251, in apply
    sub_prof = optimizer.optimize(fgraph)
AttributeError: 'SequenceDB' object has no attribute 'optimize'

ERROR (theano.gof.opt): SeqOptimizer apply <theano.gof.optdb.EquilibriumDB object at 0x114e12b50>
ERROR (theano.gof.opt): Traceback:
ERROR (theano.gof.opt): Traceback (most recent call last):
  File "/Volumes/Transcend/opt/anaconda3/envs/theano/lib/python2.7/site-packages/theano/gof/opt.py", line 251, in apply
    sub_prof = optimizer.optimize(fgraph)
AttributeError: 'EquilibriumDB' object has no attribute 'optimize'

ERROR (theano.gof.opt): SeqOptimizer apply <theano.gof.optdb.EquilibriumDB object at 0x114e12bd0>
ERROR (theano.gof.opt): Traceback:
ERROR (theano.gof.opt): Traceback (most recent call last):
  File "/Volumes/Transcend/opt/anaconda3/envs/theano/lib/python2.7/site-packages/theano/gof/opt.py", line 251, in apply
    sub_prof = optimizer.optimize(fgraph)
AttributeError: 'EquilibriumDB' object has no attribute 'optimize'

ERROR (theano.gof.opt): SeqOptimizer apply <theano.gof.optdb.EquilibriumDB object at 0x114e12c90>
ERROR (theano.gof.opt): Traceback:
ERROR (theano.gof.opt): Traceback (most recent call last):
  File "/Volumes/Transcend/opt/anaconda3/envs/theano/lib/python2.7/site-packages/theano/gof/opt.py", line 251, in apply
    sub_prof = optimizer.optimize(fgraph)
AttributeError: 'EquilibriumDB' object has no attribute 'optimize'

ERROR (theano.gof.opt): SeqOptimizer apply <theano.gof.opt.EquilibriumOptimizer object at 0x139217f10>
ERROR (theano.gof.opt): Traceback:
ERROR (theano.gof.opt): Traceback (most recent call last):
  File "/Volumes/Transcend/opt/anaconda3/envs/theano/lib/python2.7/site-packages/theano/gof/opt.py", line 251, in apply
    sub_prof = optimizer.optimize(fgraph)
  File "/Volumes/Transcend/opt/anaconda3/envs/theano/lib/python2.7/site-packages/theano/gof/opt.py", line 93, in optimize
    self.add_requirements(fgraph)
  File "/Volumes/Transcend/opt/anaconda3/envs/theano/lib/python2.7/site-packages/theano/gof/opt.py", line 2388, in add_requirements
    opt.add_requirements(fgraph)
AttributeError: 'LocalGroupDB' object has no attribute 'add_requirements'

ERROR (theano.gof.opt): SeqOptimizer apply SequenceDB (id 4783573072)
  position [('local_add_mul_fusion', 0), ('composite_elemwise_fusion', 1)]
  names set(['local_add_mul_fusion', 'composite_elemwise_fusion'])
  db DefaultOrderedDict([('local_add_mul_fusion', OrderedSet([<theano.tensor.opt.FusionOptimizer object at 0x11d1f8890>])), ('FusionOptimizer', OrderedSet([<theano.tensor.opt.FusionOptimizer object at 0x11d1f8890>, <theano.tensor.opt.FusionOptimizer object at 0x11d1f8950>])), ('fast_run', OrderedSet([<theano.tensor.opt.FusionOptimizer object at 0x11d1f8890>, <theano.tensor.opt.FusionOptimizer object at 0x11d1f8950>])), ('fusion', OrderedSet([<theano.tensor.opt.FusionOptimizer object at 0x11d1f8890>, <theano.tensor.opt.FusionOptimizer object at 0x11d1f8950>])), ('composite_elemwise_fusion', OrderedSet([<theano.tensor.opt.FusionOptimizer object at 0x11d1f8950>]))])

ERROR (theano.gof.opt): Traceback:
ERROR (theano.gof.opt): Traceback (most recent call last):
  File "/Volumes/Transcend/opt/anaconda3/envs/theano/lib/python2.7/site-packages/theano/gof/opt.py", line 251, in apply
    sub_prof = optimizer.optimize(fgraph)
AttributeError: 'SequenceDB' object has no attribute 'optimize'

ERROR (theano.gof.opt): SeqOptimizer apply <theano.gof.optdb.EquilibriumDB object at 0x12660c410>
ERROR (theano.gof.opt): Traceback:
ERROR (theano.gof.opt): Traceback (most recent call last):
  File "/Volumes/Transcend/opt/anaconda3/envs/theano/lib/python2.7/site-packages/theano/gof/opt.py", line 251, in apply
    sub_prof = optimizer.optimize(fgraph)
AttributeError: 'EquilibriumDB' object has no attribute 'optimize'

ERROR (theano.gof.opt): SeqOptimizer apply <theano.gof.opt.EquilibriumOptimizer object at 0x140a837d0>
ERROR (theano.gof.opt): Traceback:
ERROR (theano.gof.opt): Traceback (most recent call last):
  File "/Volumes/Transcend/opt/anaconda3/envs/theano/lib/python2.7/site-packages/theano/gof/opt.py", line 251, in apply
    sub_prof = optimizer.optimize(fgraph)
  File "/Volumes/Transcend/opt/anaconda3/envs/theano/lib/python2.7/site-packages/theano/gof/opt.py", line 93, in optimize
    self.add_requirements(fgraph)
  File "/Volumes/Transcend/opt/anaconda3/envs/theano/lib/python2.7/site-packages/theano/gof/opt.py", line 2388, in add_requirements
    opt.add_requirements(fgraph)
AttributeError: 'SequenceDB' object has no attribute 'add_requirements'

ERROR (theano.gof.opt): SeqOptimizer apply <theano.gof.optdb.TopoDB object at 0x114e12550>
ERROR (theano.gof.opt): Traceback:
ERROR (theano.gof.opt): Traceback (most recent call last):
  File "/Volumes/Transcend/opt/anaconda3/envs/theano/lib/python2.7/site-packages/theano/gof/opt.py", line 251, in apply
    sub_prof = optimizer.optimize(fgraph)
AttributeError: 'TopoDB' object has no attribute 'optimize'

ERROR (theano.gof.opt): SeqOptimizer apply <theano.gof.optdb.EquilibriumDB object at 0x114e12690>
ERROR (theano.gof.opt): Traceback:
ERROR (theano.gof.opt): Traceback (most recent call last):
  File "/Volumes/Transcend/opt/anaconda3/envs/theano/lib/python2.7/site-packages/theano/gof/opt.py", line 251, in apply
    sub_prof = optimizer.optimize(fgraph)
AttributeError: 'EquilibriumDB' object has no attribute 'optimize'

ERROR (theano.gof.opt): SeqOptimizer apply <theano.gof.optdb.EquilibriumDB object at 0x114e12a50>
ERROR (theano.gof.opt): Traceback:
ERROR (theano.gof.opt): Traceback (most recent call last):
  File "/Volumes/Transcend/opt/anaconda3/envs/theano/lib/python2.7/site-packages/theano/gof/opt.py", line 251, in apply
    sub_prof = optimizer.optimize(fgraph)
AttributeError: 'EquilibriumDB' object has no attribute 'optimize'

ERROR (theano.gof.opt): SeqOptimizer apply <theano.gof.optdb.EquilibriumDB object at 0x126618510>
ERROR (theano.gof.opt): Traceback:
ERROR (theano.gof.opt): Traceback (most recent call last):
  File "/Volumes/Transcend/opt/anaconda3/envs/theano/lib/python2.7/site-packages/theano/gof/opt.py", line 251, in apply
    sub_prof = optimizer.optimize(fgraph)
AttributeError: 'EquilibriumDB' object has no attribute 'optimize'

ERROR (theano.gof.opt): SeqOptimizer apply SequenceDB (id 4783785552)
  position [('local_dot_to_dot22', 0), ('gemm_optimizer', 10), ('local_dot22_to_dot22scalar', 11), ('local_gemm_to_gemv', 15), ('use_c_blas', 20), ('scipy_blas', 100)]
  names set(['gemm_optimizer', 'local_gemm_to_gemv', 'local_dot_to_dot22', 'scipy_blas', 'use_c_blas', 'local_dot22_to_dot22scalar'])
  db DefaultOrderedDict([('local_dot_to_dot22', OrderedSet([<theano.gof.opt.TopoOptimizer object at 0x11d22ce10>])), ('TopoOptimizer', OrderedSet([<theano.gof.opt.TopoOptimizer object at 0x11d22ce10>, <theano.gof.opt.TopoOptimizer object at 0x126199610>, <theano.gof.opt.TopoOptimizer object at 0x126199890>, <theano.gof.opt.TopoOptimizer object at 0x1261aa790>])), ('fast_run', OrderedSet([<theano.gof.opt.TopoOptimizer object at 0x11d22ce10>, <theano.tensor.blas.GemmOptimizer object at 0x11d22ce50>, <theano.gof.opt.EquilibriumOptimizer object at 0x1261990d0>, <theano.gof.opt.TopoOptimizer object at 0x126199610>, <theano.gof.opt.TopoOptimizer object at 0x126199890>, <theano.gof.opt.TopoOptimizer object at 0x1261aa790>])), ('fast_compile', OrderedSet([<theano.gof.opt.TopoOptimizer object at 0x11d22ce10>])), ('BlasOpt', OrderedSet([<theano.gof.opt.TopoOptimizer object at 0x11d22ce10>, <theano.tensor.blas.GemmOptimizer object at 0x11d22ce50>, <theano.gof.opt.EquilibriumOptimizer object at 0x1261990d0>, <theano.gof.opt.TopoOptimizer object at 0x126199610>, <theano.gof.opt.TopoOptimizer object at 0x126199890>, <theano.gof.opt.TopoOptimizer object at 0x1261aa790>])), ('gemm_optimizer', OrderedSet([<theano.tensor.blas.GemmOptimizer object at 0x11d22ce50>])), ('GemmOptimizer', OrderedSet([<theano.tensor.blas.GemmOptimizer object at 0x11d22ce50>])), ('local_gemm_to_gemv', OrderedSet([<theano.gof.opt.EquilibriumOptimizer object at 0x1261990d0>])), ('EquilibriumOptimizer', OrderedSet([<theano.gof.opt.EquilibriumOptimizer object at 0x1261990d0>])), ('local_dot22_to_dot22scalar', OrderedSet([<theano.gof.opt.TopoOptimizer object at 0x126199610>])), ('scipy_blas', OrderedSet([<theano.gof.opt.TopoOptimizer object at 0x126199890>])), ('use_c_blas', OrderedSet([<theano.gof.opt.TopoOptimizer object at 0x1261aa790>])), ('c_blas', OrderedSet([<theano.gof.opt.TopoOptimizer object at 0x1261aa790>]))])

ERROR (theano.gof.opt): Traceback:
ERROR (theano.gof.opt): Traceback (most recent call last):
  File "/Volumes/Transcend/opt/anaconda3/envs/theano/lib/python2.7/site-packages/theano/gof/opt.py", line 251, in apply
    sub_prof = optimizer.optimize(fgraph)
AttributeError: 'SequenceDB' object has no attribute 'optimize'

ERROR (theano.gof.opt): SeqOptimizer apply <theano.gof.optdb.EquilibriumDB object at 0x114e12b50>
ERROR (theano.gof.opt): Traceback:
ERROR (theano.gof.opt): Traceback (most recent call last):
  File "/Volumes/Transcend/opt/anaconda3/envs/theano/lib/python2.7/site-packages/theano/gof/opt.py", line 251, in apply
    sub_prof = optimizer.optimize(fgraph)
AttributeError: 'EquilibriumDB' object has no attribute 'optimize'

ERROR (theano.gof.opt): SeqOptimizer apply <theano.gof.optdb.EquilibriumDB object at 0x114e12bd0>
ERROR (theano.gof.opt): Traceback:
ERROR (theano.gof.opt): Traceback (most recent call last):
  File "/Volumes/Transcend/opt/anaconda3/envs/theano/lib/python2.7/site-packages/theano/gof/opt.py", line 251, in apply
    sub_prof = optimizer.optimize(fgraph)
AttributeError: 'EquilibriumDB' object has no attribute 'optimize'

ERROR (theano.gof.opt): SeqOptimizer apply <theano.gof.optdb.EquilibriumDB object at 0x114e12c90>
ERROR (theano.gof.opt): Traceback:
ERROR (theano.gof.opt): Traceback (most recent call last):
  File "/Volumes/Transcend/opt/anaconda3/envs/theano/lib/python2.7/site-packages/theano/gof/opt.py", line 251, in apply
    sub_prof = optimizer.optimize(fgraph)
AttributeError: 'EquilibriumDB' object has no attribute 'optimize'

ERROR (theano.gof.opt): SeqOptimizer apply <theano.gof.opt.EquilibriumOptimizer object at 0x140a83410>
ERROR (theano.gof.opt): Traceback:
ERROR (theano.gof.opt): Traceback (most recent call last):
  File "/Volumes/Transcend/opt/anaconda3/envs/theano/lib/python2.7/site-packages/theano/gof/opt.py", line 251, in apply
    sub_prof = optimizer.optimize(fgraph)
  File "/Volumes/Transcend/opt/anaconda3/envs/theano/lib/python2.7/site-packages/theano/gof/opt.py", line 93, in optimize
    self.add_requirements(fgraph)
  File "/Volumes/Transcend/opt/anaconda3/envs/theano/lib/python2.7/site-packages/theano/gof/opt.py", line 2388, in add_requirements
    opt.add_requirements(fgraph)
AttributeError: 'LocalGroupDB' object has no attribute 'add_requirements'

ERROR (theano.gof.opt): SeqOptimizer apply SequenceDB (id 4783573072)
  position [('local_add_mul_fusion', 0), ('composite_elemwise_fusion', 1)]
  names set(['local_add_mul_fusion', 'composite_elemwise_fusion'])
  db DefaultOrderedDict([('local_add_mul_fusion', OrderedSet([<theano.tensor.opt.FusionOptimizer object at 0x11d1f8890>])), ('FusionOptimizer', OrderedSet([<theano.tensor.opt.FusionOptimizer object at 0x11d1f8890>, <theano.tensor.opt.FusionOptimizer object at 0x11d1f8950>])), ('fast_run', OrderedSet([<theano.tensor.opt.FusionOptimizer object at 0x11d1f8890>, <theano.tensor.opt.FusionOptimizer object at 0x11d1f8950>])), ('fusion', OrderedSet([<theano.tensor.opt.FusionOptimizer object at 0x11d1f8890>, <theano.tensor.opt.FusionOptimizer object at 0x11d1f8950>])), ('composite_elemwise_fusion', OrderedSet([<theano.tensor.opt.FusionOptimizer object at 0x11d1f8950>]))])

ERROR (theano.gof.opt): Traceback:
ERROR (theano.gof.opt): Traceback (most recent call last):
  File "/Volumes/Transcend/opt/anaconda3/envs/theano/lib/python2.7/site-packages/theano/gof/opt.py", line 251, in apply
    sub_prof = optimizer.optimize(fgraph)
AttributeError: 'SequenceDB' object has no attribute 'optimize'

ERROR (theano.gof.opt): SeqOptimizer apply <theano.gof.optdb.EquilibriumDB object at 0x12660c410>
ERROR (theano.gof.opt): Traceback:
ERROR (theano.gof.opt): Traceback (most recent call last):
  File "/Volumes/Transcend/opt/anaconda3/envs/theano/lib/python2.7/site-packages/theano/gof/opt.py", line 251, in apply
    sub_prof = optimizer.optimize(fgraph)
AttributeError: 'EquilibriumDB' object has no attribute 'optimize'

ERROR (theano.gof.opt): SeqOptimizer apply <theano.gof.opt.EquilibriumOptimizer object at 0x140a83810>
ERROR (theano.gof.opt): Traceback:
ERROR (theano.gof.opt): Traceback (most recent call last):
  File "/Volumes/Transcend/opt/anaconda3/envs/theano/lib/python2.7/site-packages/theano/gof/opt.py", line 251, in apply
    sub_prof = optimizer.optimize(fgraph)
  File "/Volumes/Transcend/opt/anaconda3/envs/theano/lib/python2.7/site-packages/theano/gof/opt.py", line 93, in optimize
    self.add_requirements(fgraph)
  File "/Volumes/Transcend/opt/anaconda3/envs/theano/lib/python2.7/site-packages/theano/gof/opt.py", line 2388, in add_requirements
    opt.add_requirements(fgraph)
AttributeError: 'SequenceDB' object has no attribute 'add_requirements'

ERROR (theano.gof.opt): SeqOptimizer apply <theano.gof.optdb.TopoDB object at 0x114e12550>
ERROR (theano.gof.opt): Traceback:
ERROR (theano.gof.opt): Traceback (most recent call last):
  File "/Volumes/Transcend/opt/anaconda3/envs/theano/lib/python2.7/site-packages/theano/gof/opt.py", line 251, in apply
    sub_prof = optimizer.optimize(fgraph)
AttributeError: 'TopoDB' object has no attribute 'optimize'

ERROR (theano.gof.opt): SeqOptimizer apply <theano.gof.optdb.EquilibriumDB object at 0x114e12690>
ERROR (theano.gof.opt): Traceback:
ERROR (theano.gof.opt): Traceback (most recent call last):
  File "/Volumes/Transcend/opt/anaconda3/envs/theano/lib/python2.7/site-packages/theano/gof/opt.py", line 251, in apply
    sub_prof = optimizer.optimize(fgraph)
AttributeError: 'EquilibriumDB' object has no attribute 'optimize'

ERROR (theano.gof.opt): SeqOptimizer apply <theano.gof.optdb.EquilibriumDB object at 0x114e12a50>
ERROR (theano.gof.opt): Traceback:
ERROR (theano.gof.opt): Traceback (most recent call last):
  File "/Volumes/Transcend/opt/anaconda3/envs/theano/lib/python2.7/site-packages/theano/gof/opt.py", line 251, in apply
    sub_prof = optimizer.optimize(fgraph)
AttributeError: 'EquilibriumDB' object has no attribute 'optimize'

ERROR (theano.gof.opt): SeqOptimizer apply <theano.gof.optdb.EquilibriumDB object at 0x126618510>
ERROR (theano.gof.opt): Traceback:
ERROR (theano.gof.opt): Traceback (most recent call last):
  File "/Volumes/Transcend/opt/anaconda3/envs/theano/lib/python2.7/site-packages/theano/gof/opt.py", line 251, in apply
    sub_prof = optimizer.optimize(fgraph)
AttributeError: 'EquilibriumDB' object has no attribute 'optimize'

ERROR (theano.gof.opt): SeqOptimizer apply SequenceDB (id 4783785552)
  position [('local_dot_to_dot22', 0), ('gemm_optimizer', 10), ('local_dot22_to_dot22scalar', 11), ('local_gemm_to_gemv', 15), ('use_c_blas', 20), ('scipy_blas', 100)]
  names set(['gemm_optimizer', 'local_gemm_to_gemv', 'local_dot_to_dot22', 'scipy_blas', 'use_c_blas', 'local_dot22_to_dot22scalar'])
  db DefaultOrderedDict([('local_dot_to_dot22', OrderedSet([<theano.gof.opt.TopoOptimizer object at 0x11d22ce10>])), ('TopoOptimizer', OrderedSet([<theano.gof.opt.TopoOptimizer object at 0x11d22ce10>, <theano.gof.opt.TopoOptimizer object at 0x126199610>, <theano.gof.opt.TopoOptimizer object at 0x126199890>, <theano.gof.opt.TopoOptimizer object at 0x1261aa790>])), ('fast_run', OrderedSet([<theano.gof.opt.TopoOptimizer object at 0x11d22ce10>, <theano.tensor.blas.GemmOptimizer object at 0x11d22ce50>, <theano.gof.opt.EquilibriumOptimizer object at 0x1261990d0>, <theano.gof.opt.TopoOptimizer object at 0x126199610>, <theano.gof.opt.TopoOptimizer object at 0x126199890>, <theano.gof.opt.TopoOptimizer object at 0x1261aa790>])), ('fast_compile', OrderedSet([<theano.gof.opt.TopoOptimizer object at 0x11d22ce10>])), ('BlasOpt', OrderedSet([<theano.gof.opt.TopoOptimizer object at 0x11d22ce10>, <theano.tensor.blas.GemmOptimizer object at 0x11d22ce50>, <theano.gof.opt.EquilibriumOptimizer object at 0x1261990d0>, <theano.gof.opt.TopoOptimizer object at 0x126199610>, <theano.gof.opt.TopoOptimizer object at 0x126199890>, <theano.gof.opt.TopoOptimizer object at 0x1261aa790>])), ('gemm_optimizer', OrderedSet([<theano.tensor.blas.GemmOptimizer object at 0x11d22ce50>])), ('GemmOptimizer', OrderedSet([<theano.tensor.blas.GemmOptimizer object at 0x11d22ce50>])), ('local_gemm_to_gemv', OrderedSet([<theano.gof.opt.EquilibriumOptimizer object at 0x1261990d0>])), ('EquilibriumOptimizer', OrderedSet([<theano.gof.opt.EquilibriumOptimizer object at 0x1261990d0>])), ('local_dot22_to_dot22scalar', OrderedSet([<theano.gof.opt.TopoOptimizer object at 0x126199610>])), ('scipy_blas', OrderedSet([<theano.gof.opt.TopoOptimizer object at 0x126199890>])), ('use_c_blas', OrderedSet([<theano.gof.opt.TopoOptimizer object at 0x1261aa790>])), ('c_blas', OrderedSet([<theano.gof.opt.TopoOptimizer object at 0x1261aa790>]))])

ERROR (theano.gof.opt): Traceback:
ERROR (theano.gof.opt): Traceback (most recent call last):
  File "/Volumes/Transcend/opt/anaconda3/envs/theano/lib/python2.7/site-packages/theano/gof/opt.py", line 251, in apply
    sub_prof = optimizer.optimize(fgraph)
AttributeError: 'SequenceDB' object has no attribute 'optimize'

ERROR (theano.gof.opt): SeqOptimizer apply <theano.gof.optdb.EquilibriumDB object at 0x114e12b50>
ERROR (theano.gof.opt): Traceback:
ERROR (theano.gof.opt): Traceback (most recent call last):
  File "/Volumes/Transcend/opt/anaconda3/envs/theano/lib/python2.7/site-packages/theano/gof/opt.py", line 251, in apply
    sub_prof = optimizer.optimize(fgraph)
AttributeError: 'EquilibriumDB' object has no attribute 'optimize'

ERROR (theano.gof.opt): SeqOptimizer apply <theano.gof.optdb.EquilibriumDB object at 0x114e12bd0>
ERROR (theano.gof.opt): Traceback:
ERROR (theano.gof.opt): Traceback (most recent call last):
  File "/Volumes/Transcend/opt/anaconda3/envs/theano/lib/python2.7/site-packages/theano/gof/opt.py", line 251, in apply
    sub_prof = optimizer.optimize(fgraph)
AttributeError: 'EquilibriumDB' object has no attribute 'optimize'

ERROR (theano.gof.opt): SeqOptimizer apply <theano.gof.optdb.EquilibriumDB object at 0x114e12c90>
ERROR (theano.gof.opt): Traceback:
ERROR (theano.gof.opt): Traceback (most recent call last):
  File "/Volumes/Transcend/opt/anaconda3/envs/theano/lib/python2.7/site-packages/theano/gof/opt.py", line 251, in apply
    sub_prof = optimizer.optimize(fgraph)
AttributeError: 'EquilibriumDB' object has no attribute 'optimize'

ERROR (theano.gof.opt): SeqOptimizer apply <theano.gof.opt.EquilibriumOptimizer object at 0x13fae2590>
ERROR (theano.gof.opt): Traceback:
ERROR (theano.gof.opt): Traceback (most recent call last):
  File "/Volumes/Transcend/opt/anaconda3/envs/theano/lib/python2.7/site-packages/theano/gof/opt.py", line 251, in apply
    sub_prof = optimizer.optimize(fgraph)
  File "/Volumes/Transcend/opt/anaconda3/envs/theano/lib/python2.7/site-packages/theano/gof/opt.py", line 93, in optimize
    self.add_requirements(fgraph)
  File "/Volumes/Transcend/opt/anaconda3/envs/theano/lib/python2.7/site-packages/theano/gof/opt.py", line 2388, in add_requirements
    opt.add_requirements(fgraph)
AttributeError: 'LocalGroupDB' object has no attribute 'add_requirements'

ERROR (theano.gof.opt): SeqOptimizer apply SequenceDB (id 4783573072)
  position [('local_add_mul_fusion', 0), ('composite_elemwise_fusion', 1)]
  names set(['local_add_mul_fusion', 'composite_elemwise_fusion'])
  db DefaultOrderedDict([('local_add_mul_fusion', OrderedSet([<theano.tensor.opt.FusionOptimizer object at 0x11d1f8890>])), ('FusionOptimizer', OrderedSet([<theano.tensor.opt.FusionOptimizer object at 0x11d1f8890>, <theano.tensor.opt.FusionOptimizer object at 0x11d1f8950>])), ('fast_run', OrderedSet([<theano.tensor.opt.FusionOptimizer object at 0x11d1f8890>, <theano.tensor.opt.FusionOptimizer object at 0x11d1f8950>])), ('fusion', OrderedSet([<theano.tensor.opt.FusionOptimizer object at 0x11d1f8890>, <theano.tensor.opt.FusionOptimizer object at 0x11d1f8950>])), ('composite_elemwise_fusion', OrderedSet([<theano.tensor.opt.FusionOptimizer object at 0x11d1f8950>]))])

ERROR (theano.gof.opt): Traceback:
ERROR (theano.gof.opt): Traceback (most recent call last):
  File "/Volumes/Transcend/opt/anaconda3/envs/theano/lib/python2.7/site-packages/theano/gof/opt.py", line 251, in apply
    sub_prof = optimizer.optimize(fgraph)
AttributeError: 'SequenceDB' object has no attribute 'optimize'

ERROR (theano.gof.opt): SeqOptimizer apply <theano.gof.optdb.EquilibriumDB object at 0x12660c410>
ERROR (theano.gof.opt): Traceback:
ERROR (theano.gof.opt): Traceback (most recent call last):
  File "/Volumes/Transcend/opt/anaconda3/envs/theano/lib/python2.7/site-packages/theano/gof/opt.py", line 251, in apply
    sub_prof = optimizer.optimize(fgraph)
AttributeError: 'EquilibriumDB' object has no attribute 'optimize'

ERROR (theano.gof.opt): SeqOptimizer apply <theano.gof.opt.EquilibriumOptimizer object at 0x1299e37d0>
ERROR (theano.gof.opt): Traceback:
ERROR (theano.gof.opt): Traceback (most recent call last):
  File "/Volumes/Transcend/opt/anaconda3/envs/theano/lib/python2.7/site-packages/theano/gof/opt.py", line 251, in apply
    sub_prof = optimizer.optimize(fgraph)
  File "/Volumes/Transcend/opt/anaconda3/envs/theano/lib/python2.7/site-packages/theano/gof/opt.py", line 93, in optimize
    self.add_requirements(fgraph)
  File "/Volumes/Transcend/opt/anaconda3/envs/theano/lib/python2.7/site-packages/theano/gof/opt.py", line 2388, in add_requirements
    opt.add_requirements(fgraph)
AttributeError: 'SequenceDB' object has no attribute 'add_requirements'

ERROR (theano.gof.opt): SeqOptimizer apply <theano.gof.optdb.TopoDB object at 0x114e12550>
ERROR (theano.gof.opt): Traceback:
ERROR (theano.gof.opt): Traceback (most recent call last):
  File "/Volumes/Transcend/opt/anaconda3/envs/theano/lib/python2.7/site-packages/theano/gof/opt.py", line 251, in apply
    sub_prof = optimizer.optimize(fgraph)
AttributeError: 'TopoDB' object has no attribute 'optimize'

ERROR (theano.gof.opt): SeqOptimizer apply <theano.gof.optdb.EquilibriumDB object at 0x114e12690>
ERROR (theano.gof.opt): Traceback:
ERROR (theano.gof.opt): Traceback (most recent call last):
  File "/Volumes/Transcend/opt/anaconda3/envs/theano/lib/python2.7/site-packages/theano/gof/opt.py", line 251, in apply
    sub_prof = optimizer.optimize(fgraph)
AttributeError: 'EquilibriumDB' object has no attribute 'optimize'

ERROR (theano.gof.opt): SeqOptimizer apply <theano.gof.optdb.EquilibriumDB object at 0x114e12a50>
ERROR (theano.gof.opt): Traceback:
ERROR (theano.gof.opt): Traceback (most recent call last):
  File "/Volumes/Transcend/opt/anaconda3/envs/theano/lib/python2.7/site-packages/theano/gof/opt.py", line 251, in apply
    sub_prof = optimizer.optimize(fgraph)
AttributeError: 'EquilibriumDB' object has no attribute 'optimize'

ERROR (theano.gof.opt): SeqOptimizer apply <theano.gof.optdb.EquilibriumDB object at 0x126618510>
ERROR (theano.gof.opt): Traceback:
ERROR (theano.gof.opt): Traceback (most recent call last):
  File "/Volumes/Transcend/opt/anaconda3/envs/theano/lib/python2.7/site-packages/theano/gof/opt.py", line 251, in apply
    sub_prof = optimizer.optimize(fgraph)
AttributeError: 'EquilibriumDB' object has no attribute 'optimize'

ERROR (theano.gof.opt): SeqOptimizer apply SequenceDB (id 4783785552)
  position [('local_dot_to_dot22', 0), ('gemm_optimizer', 10), ('local_dot22_to_dot22scalar', 11), ('local_gemm_to_gemv', 15), ('use_c_blas', 20), ('scipy_blas', 100)]
  names set(['gemm_optimizer', 'local_gemm_to_gemv', 'local_dot_to_dot22', 'scipy_blas', 'use_c_blas', 'local_dot22_to_dot22scalar'])
  db DefaultOrderedDict([('local_dot_to_dot22', OrderedSet([<theano.gof.opt.TopoOptimizer object at 0x11d22ce10>])), ('TopoOptimizer', OrderedSet([<theano.gof.opt.TopoOptimizer object at 0x11d22ce10>, <theano.gof.opt.TopoOptimizer object at 0x126199610>, <theano.gof.opt.TopoOptimizer object at 0x126199890>, <theano.gof.opt.TopoOptimizer object at 0x1261aa790>])), ('fast_run', OrderedSet([<theano.gof.opt.TopoOptimizer object at 0x11d22ce10>, <theano.tensor.blas.GemmOptimizer object at 0x11d22ce50>, <theano.gof.opt.EquilibriumOptimizer object at 0x1261990d0>, <theano.gof.opt.TopoOptimizer object at 0x126199610>, <theano.gof.opt.TopoOptimizer object at 0x126199890>, <theano.gof.opt.TopoOptimizer object at 0x1261aa790>])), ('fast_compile', OrderedSet([<theano.gof.opt.TopoOptimizer object at 0x11d22ce10>])), ('BlasOpt', OrderedSet([<theano.gof.opt.TopoOptimizer object at 0x11d22ce10>, <theano.tensor.blas.GemmOptimizer object at 0x11d22ce50>, <theano.gof.opt.EquilibriumOptimizer object at 0x1261990d0>, <theano.gof.opt.TopoOptimizer object at 0x126199610>, <theano.gof.opt.TopoOptimizer object at 0x126199890>, <theano.gof.opt.TopoOptimizer object at 0x1261aa790>])), ('gemm_optimizer', OrderedSet([<theano.tensor.blas.GemmOptimizer object at 0x11d22ce50>])), ('GemmOptimizer', OrderedSet([<theano.tensor.blas.GemmOptimizer object at 0x11d22ce50>])), ('local_gemm_to_gemv', OrderedSet([<theano.gof.opt.EquilibriumOptimizer object at 0x1261990d0>])), ('EquilibriumOptimizer', OrderedSet([<theano.gof.opt.EquilibriumOptimizer object at 0x1261990d0>])), ('local_dot22_to_dot22scalar', OrderedSet([<theano.gof.opt.TopoOptimizer object at 0x126199610>])), ('scipy_blas', OrderedSet([<theano.gof.opt.TopoOptimizer object at 0x126199890>])), ('use_c_blas', OrderedSet([<theano.gof.opt.TopoOptimizer object at 0x1261aa790>])), ('c_blas', OrderedSet([<theano.gof.opt.TopoOptimizer object at 0x1261aa790>]))])

ERROR (theano.gof.opt): Traceback:
ERROR (theano.gof.opt): Traceback (most recent call last):
  File "/Volumes/Transcend/opt/anaconda3/envs/theano/lib/python2.7/site-packages/theano/gof/opt.py", line 251, in apply
    sub_prof = optimizer.optimize(fgraph)
AttributeError: 'SequenceDB' object has no attribute 'optimize'

ERROR (theano.gof.opt): SeqOptimizer apply <theano.gof.optdb.EquilibriumDB object at 0x114e12b50>
ERROR (theano.gof.opt): Traceback:
ERROR (theano.gof.opt): Traceback (most recent call last):
  File "/Volumes/Transcend/opt/anaconda3/envs/theano/lib/python2.7/site-packages/theano/gof/opt.py", line 251, in apply
    sub_prof = optimizer.optimize(fgraph)
AttributeError: 'EquilibriumDB' object has no attribute 'optimize'

ERROR (theano.gof.opt): SeqOptimizer apply <theano.gof.optdb.EquilibriumDB object at 0x114e12bd0>
ERROR (theano.gof.opt): Traceback:
ERROR (theano.gof.opt): Traceback (most recent call last):
  File "/Volumes/Transcend/opt/anaconda3/envs/theano/lib/python2.7/site-packages/theano/gof/opt.py", line 251, in apply
    sub_prof = optimizer.optimize(fgraph)
AttributeError: 'EquilibriumDB' object has no attribute 'optimize'

ERROR (theano.gof.opt): SeqOptimizer apply <theano.gof.optdb.EquilibriumDB object at 0x114e12c90>
ERROR (theano.gof.opt): Traceback:
ERROR (theano.gof.opt): Traceback (most recent call last):
  File "/Volumes/Transcend/opt/anaconda3/envs/theano/lib/python2.7/site-packages/theano/gof/opt.py", line 251, in apply
    sub_prof = optimizer.optimize(fgraph)
AttributeError: 'EquilibriumDB' object has no attribute 'optimize'

ERROR (theano.gof.opt): SeqOptimizer apply <theano.gof.opt.EquilibriumOptimizer object at 0x129a74e90>
ERROR (theano.gof.opt): Traceback:
ERROR (theano.gof.opt): Traceback (most recent call last):
  File "/Volumes/Transcend/opt/anaconda3/envs/theano/lib/python2.7/site-packages/theano/gof/opt.py", line 251, in apply
    sub_prof = optimizer.optimize(fgraph)
  File "/Volumes/Transcend/opt/anaconda3/envs/theano/lib/python2.7/site-packages/theano/gof/opt.py", line 93, in optimize
    self.add_requirements(fgraph)
  File "/Volumes/Transcend/opt/anaconda3/envs/theano/lib/python2.7/site-packages/theano/gof/opt.py", line 2388, in add_requirements
    opt.add_requirements(fgraph)
AttributeError: 'LocalGroupDB' object has no attribute 'add_requirements'

ERROR (theano.gof.opt): SeqOptimizer apply SequenceDB (id 4783573072)
  position [('local_add_mul_fusion', 0), ('composite_elemwise_fusion', 1)]
  names set(['local_add_mul_fusion', 'composite_elemwise_fusion'])
  db DefaultOrderedDict([('local_add_mul_fusion', OrderedSet([<theano.tensor.opt.FusionOptimizer object at 0x11d1f8890>])), ('FusionOptimizer', OrderedSet([<theano.tensor.opt.FusionOptimizer object at 0x11d1f8890>, <theano.tensor.opt.FusionOptimizer object at 0x11d1f8950>])), ('fast_run', OrderedSet([<theano.tensor.opt.FusionOptimizer object at 0x11d1f8890>, <theano.tensor.opt.FusionOptimizer object at 0x11d1f8950>])), ('fusion', OrderedSet([<theano.tensor.opt.FusionOptimizer object at 0x11d1f8890>, <theano.tensor.opt.FusionOptimizer object at 0x11d1f8950>])), ('composite_elemwise_fusion', OrderedSet([<theano.tensor.opt.FusionOptimizer object at 0x11d1f8950>]))])

ERROR (theano.gof.opt): Traceback:
ERROR (theano.gof.opt): Traceback (most recent call last):
  File "/Volumes/Transcend/opt/anaconda3/envs/theano/lib/python2.7/site-packages/theano/gof/opt.py", line 251, in apply
    sub_prof = optimizer.optimize(fgraph)
AttributeError: 'SequenceDB' object has no attribute 'optimize'

ERROR (theano.gof.opt): SeqOptimizer apply <theano.gof.optdb.EquilibriumDB object at 0x12660c410>
ERROR (theano.gof.opt): Traceback:
ERROR (theano.gof.opt): Traceback (most recent call last):
  File "/Volumes/Transcend/opt/anaconda3/envs/theano/lib/python2.7/site-packages/theano/gof/opt.py", line 251, in apply
    sub_prof = optimizer.optimize(fgraph)
AttributeError: 'EquilibriumDB' object has no attribute 'optimize'

ERROR (theano.gof.opt): SeqOptimizer apply <theano.gof.opt.EquilibriumOptimizer object at 0x138ccdad0>
ERROR (theano.gof.opt): Traceback:
ERROR (theano.gof.opt): Traceback (most recent call last):
  File "/Volumes/Transcend/opt/anaconda3/envs/theano/lib/python2.7/site-packages/theano/gof/opt.py", line 251, in apply
    sub_prof = optimizer.optimize(fgraph)
  File "/Volumes/Transcend/opt/anaconda3/envs/theano/lib/python2.7/site-packages/theano/gof/opt.py", line 93, in optimize
    self.add_requirements(fgraph)
  File "/Volumes/Transcend/opt/anaconda3/envs/theano/lib/python2.7/site-packages/theano/gof/opt.py", line 2388, in add_requirements
    opt.add_requirements(fgraph)
AttributeError: 'SequenceDB' object has no attribute 'add_requirements'

ERROR (theano.gof.opt): SeqOptimizer apply <theano.gof.optdb.TopoDB object at 0x114e12550>
ERROR (theano.gof.opt): Traceback:
ERROR (theano.gof.opt): Traceback (most recent call last):
  File "/Volumes/Transcend/opt/anaconda3/envs/theano/lib/python2.7/site-packages/theano/gof/opt.py", line 251, in apply
    sub_prof = optimizer.optimize(fgraph)
AttributeError: 'TopoDB' object has no attribute 'optimize'

ERROR (theano.gof.opt): SeqOptimizer apply <theano.gof.optdb.EquilibriumDB object at 0x114e12690>
ERROR (theano.gof.opt): Traceback:
ERROR (theano.gof.opt): Traceback (most recent call last):
  File "/Volumes/Transcend/opt/anaconda3/envs/theano/lib/python2.7/site-packages/theano/gof/opt.py", line 251, in apply
    sub_prof = optimizer.optimize(fgraph)
AttributeError: 'EquilibriumDB' object has no attribute 'optimize'

ERROR (theano.gof.opt): SeqOptimizer apply <theano.gof.optdb.EquilibriumDB object at 0x114e12a50>
ERROR (theano.gof.opt): Traceback:
ERROR (theano.gof.opt): Traceback (most recent call last):
  File "/Volumes/Transcend/opt/anaconda3/envs/theano/lib/python2.7/site-packages/theano/gof/opt.py", line 251, in apply
    sub_prof = optimizer.optimize(fgraph)
AttributeError: 'EquilibriumDB' object has no attribute 'optimize'

ERROR (theano.gof.opt): SeqOptimizer apply <theano.gof.optdb.EquilibriumDB object at 0x126618510>
ERROR (theano.gof.opt): Traceback:
ERROR (theano.gof.opt): Traceback (most recent call last):
  File "/Volumes/Transcend/opt/anaconda3/envs/theano/lib/python2.7/site-packages/theano/gof/opt.py", line 251, in apply
    sub_prof = optimizer.optimize(fgraph)
AttributeError: 'EquilibriumDB' object has no attribute 'optimize'

ERROR (theano.gof.opt): SeqOptimizer apply SequenceDB (id 4783785552)
  position [('local_dot_to_dot22', 0), ('gemm_optimizer', 10), ('local_dot22_to_dot22scalar', 11), ('local_gemm_to_gemv', 15), ('use_c_blas', 20), ('scipy_blas', 100)]
  names set(['gemm_optimizer', 'local_gemm_to_gemv', 'local_dot_to_dot22', 'scipy_blas', 'use_c_blas', 'local_dot22_to_dot22scalar'])
  db DefaultOrderedDict([('local_dot_to_dot22', OrderedSet([<theano.gof.opt.TopoOptimizer object at 0x11d22ce10>])), ('TopoOptimizer', OrderedSet([<theano.gof.opt.TopoOptimizer object at 0x11d22ce10>, <theano.gof.opt.TopoOptimizer object at 0x126199610>, <theano.gof.opt.TopoOptimizer object at 0x126199890>, <theano.gof.opt.TopoOptimizer object at 0x1261aa790>])), ('fast_run', OrderedSet([<theano.gof.opt.TopoOptimizer object at 0x11d22ce10>, <theano.tensor.blas.GemmOptimizer object at 0x11d22ce50>, <theano.gof.opt.EquilibriumOptimizer object at 0x1261990d0>, <theano.gof.opt.TopoOptimizer object at 0x126199610>, <theano.gof.opt.TopoOptimizer object at 0x126199890>, <theano.gof.opt.TopoOptimizer object at 0x1261aa790>])), ('fast_compile', OrderedSet([<theano.gof.opt.TopoOptimizer object at 0x11d22ce10>])), ('BlasOpt', OrderedSet([<theano.gof.opt.TopoOptimizer object at 0x11d22ce10>, <theano.tensor.blas.GemmOptimizer object at 0x11d22ce50>, <theano.gof.opt.EquilibriumOptimizer object at 0x1261990d0>, <theano.gof.opt.TopoOptimizer object at 0x126199610>, <theano.gof.opt.TopoOptimizer object at 0x126199890>, <theano.gof.opt.TopoOptimizer object at 0x1261aa790>])), ('gemm_optimizer', OrderedSet([<theano.tensor.blas.GemmOptimizer object at 0x11d22ce50>])), ('GemmOptimizer', OrderedSet([<theano.tensor.blas.GemmOptimizer object at 0x11d22ce50>])), ('local_gemm_to_gemv', OrderedSet([<theano.gof.opt.EquilibriumOptimizer object at 0x1261990d0>])), ('EquilibriumOptimizer', OrderedSet([<theano.gof.opt.EquilibriumOptimizer object at 0x1261990d0>])), ('local_dot22_to_dot22scalar', OrderedSet([<theano.gof.opt.TopoOptimizer object at 0x126199610>])), ('scipy_blas', OrderedSet([<theano.gof.opt.TopoOptimizer object at 0x126199890>])), ('use_c_blas', OrderedSet([<theano.gof.opt.TopoOptimizer object at 0x1261aa790>])), ('c_blas', OrderedSet([<theano.gof.opt.TopoOptimizer object at 0x1261aa790>]))])

ERROR (theano.gof.opt): Traceback:
ERROR (theano.gof.opt): Traceback (most recent call last):
  File "/Volumes/Transcend/opt/anaconda3/envs/theano/lib/python2.7/site-packages/theano/gof/opt.py", line 251, in apply
    sub_prof = optimizer.optimize(fgraph)
AttributeError: 'SequenceDB' object has no attribute 'optimize'

ERROR (theano.gof.opt): SeqOptimizer apply <theano.gof.optdb.EquilibriumDB object at 0x114e12b50>
ERROR (theano.gof.opt): Traceback:
ERROR (theano.gof.opt): Traceback (most recent call last):
  File "/Volumes/Transcend/opt/anaconda3/envs/theano/lib/python2.7/site-packages/theano/gof/opt.py", line 251, in apply
    sub_prof = optimizer.optimize(fgraph)
AttributeError: 'EquilibriumDB' object has no attribute 'optimize'

ERROR (theano.gof.opt): SeqOptimizer apply <theano.gof.optdb.EquilibriumDB object at 0x114e12bd0>
ERROR (theano.gof.opt): Traceback:
ERROR (theano.gof.opt): Traceback (most recent call last):
  File "/Volumes/Transcend/opt/anaconda3/envs/theano/lib/python2.7/site-packages/theano/gof/opt.py", line 251, in apply
    sub_prof = optimizer.optimize(fgraph)
AttributeError: 'EquilibriumDB' object has no attribute 'optimize'

ERROR (theano.gof.opt): SeqOptimizer apply <theano.gof.optdb.EquilibriumDB object at 0x114e12c90>
ERROR (theano.gof.opt): Traceback:
ERROR (theano.gof.opt): Traceback (most recent call last):
  File "/Volumes/Transcend/opt/anaconda3/envs/theano/lib/python2.7/site-packages/theano/gof/opt.py", line 251, in apply
    sub_prof = optimizer.optimize(fgraph)
AttributeError: 'EquilibriumDB' object has no attribute 'optimize'

ERROR (theano.gof.opt): SeqOptimizer apply <theano.gof.opt.EquilibriumOptimizer object at 0x138ccd0d0>
ERROR (theano.gof.opt): Traceback:
ERROR (theano.gof.opt): Traceback (most recent call last):
  File "/Volumes/Transcend/opt/anaconda3/envs/theano/lib/python2.7/site-packages/theano/gof/opt.py", line 251, in apply
    sub_prof = optimizer.optimize(fgraph)
  File "/Volumes/Transcend/opt/anaconda3/envs/theano/lib/python2.7/site-packages/theano/gof/opt.py", line 93, in optimize
    self.add_requirements(fgraph)
  File "/Volumes/Transcend/opt/anaconda3/envs/theano/lib/python2.7/site-packages/theano/gof/opt.py", line 2388, in add_requirements
    opt.add_requirements(fgraph)
AttributeError: 'LocalGroupDB' object has no attribute 'add_requirements'

ERROR (theano.gof.opt): SeqOptimizer apply SequenceDB (id 4783573072)
  position [('local_add_mul_fusion', 0), ('composite_elemwise_fusion', 1)]
  names set(['local_add_mul_fusion', 'composite_elemwise_fusion'])
  db DefaultOrderedDict([('local_add_mul_fusion', OrderedSet([<theano.tensor.opt.FusionOptimizer object at 0x11d1f8890>])), ('FusionOptimizer', OrderedSet([<theano.tensor.opt.FusionOptimizer object at 0x11d1f8890>, <theano.tensor.opt.FusionOptimizer object at 0x11d1f8950>])), ('fast_run', OrderedSet([<theano.tensor.opt.FusionOptimizer object at 0x11d1f8890>, <theano.tensor.opt.FusionOptimizer object at 0x11d1f8950>])), ('fusion', OrderedSet([<theano.tensor.opt.FusionOptimizer object at 0x11d1f8890>, <theano.tensor.opt.FusionOptimizer object at 0x11d1f8950>])), ('composite_elemwise_fusion', OrderedSet([<theano.tensor.opt.FusionOptimizer object at 0x11d1f8950>]))])

ERROR (theano.gof.opt): Traceback:
ERROR (theano.gof.opt): Traceback (most recent call last):
  File "/Volumes/Transcend/opt/anaconda3/envs/theano/lib/python2.7/site-packages/theano/gof/opt.py", line 251, in apply
    sub_prof = optimizer.optimize(fgraph)
AttributeError: 'SequenceDB' object has no attribute 'optimize'

ERROR (theano.gof.opt): SeqOptimizer apply <theano.gof.optdb.EquilibriumDB object at 0x12660c410>
ERROR (theano.gof.opt): Traceback:
ERROR (theano.gof.opt): Traceback (most recent call last):
  File "/Volumes/Transcend/opt/anaconda3/envs/theano/lib/python2.7/site-packages/theano/gof/opt.py", line 251, in apply
    sub_prof = optimizer.optimize(fgraph)
AttributeError: 'EquilibriumDB' object has no attribute 'optimize'

ERROR (theano.gof.opt): SeqOptimizer apply <theano.gof.opt.EquilibriumOptimizer object at 0x1400567d0>
ERROR (theano.gof.opt): Traceback:
ERROR (theano.gof.opt): Traceback (most recent call last):
  File "/Volumes/Transcend/opt/anaconda3/envs/theano/lib/python2.7/site-packages/theano/gof/opt.py", line 251, in apply
    sub_prof = optimizer.optimize(fgraph)
  File "/Volumes/Transcend/opt/anaconda3/envs/theano/lib/python2.7/site-packages/theano/gof/opt.py", line 93, in optimize
    self.add_requirements(fgraph)
  File "/Volumes/Transcend/opt/anaconda3/envs/theano/lib/python2.7/site-packages/theano/gof/opt.py", line 2388, in add_requirements
    opt.add_requirements(fgraph)
AttributeError: 'SequenceDB' object has no attribute 'add_requirements'

ERROR (theano.gof.opt): SeqOptimizer apply <theano.gof.optdb.TopoDB object at 0x114e12550>
ERROR (theano.gof.opt): Traceback:
ERROR (theano.gof.opt): Traceback (most recent call last):
  File "/Volumes/Transcend/opt/anaconda3/envs/theano/lib/python2.7/site-packages/theano/gof/opt.py", line 251, in apply
    sub_prof = optimizer.optimize(fgraph)
AttributeError: 'TopoDB' object has no attribute 'optimize'

ERROR (theano.gof.opt): SeqOptimizer apply <theano.gof.optdb.EquilibriumDB object at 0x114e12690>
ERROR (theano.gof.opt): Traceback:
ERROR (theano.gof.opt): Traceback (most recent call last):
  File "/Volumes/Transcend/opt/anaconda3/envs/theano/lib/python2.7/site-packages/theano/gof/opt.py", line 251, in apply
    sub_prof = optimizer.optimize(fgraph)
AttributeError: 'EquilibriumDB' object has no attribute 'optimize'

ERROR (theano.gof.opt): SeqOptimizer apply <theano.gof.optdb.EquilibriumDB object at 0x114e12a50>
ERROR (theano.gof.opt): Traceback:
ERROR (theano.gof.opt): Traceback (most recent call last):
  File "/Volumes/Transcend/opt/anaconda3/envs/theano/lib/python2.7/site-packages/theano/gof/opt.py", line 251, in apply
    sub_prof = optimizer.optimize(fgraph)
AttributeError: 'EquilibriumDB' object has no attribute 'optimize'

ERROR (theano.gof.opt): SeqOptimizer apply <theano.gof.optdb.EquilibriumDB object at 0x126618510>
ERROR (theano.gof.opt): Traceback:
ERROR (theano.gof.opt): Traceback (most recent call last):
  File "/Volumes/Transcend/opt/anaconda3/envs/theano/lib/python2.7/site-packages/theano/gof/opt.py", line 251, in apply
    sub_prof = optimizer.optimize(fgraph)
AttributeError: 'EquilibriumDB' object has no attribute 'optimize'

ERROR (theano.gof.opt): SeqOptimizer apply SequenceDB (id 4783785552)
  position [('local_dot_to_dot22', 0), ('gemm_optimizer', 10), ('local_dot22_to_dot22scalar', 11), ('local_gemm_to_gemv', 15), ('use_c_blas', 20), ('scipy_blas', 100)]
  names set(['gemm_optimizer', 'local_gemm_to_gemv', 'local_dot_to_dot22', 'scipy_blas', 'use_c_blas', 'local_dot22_to_dot22scalar'])
  db DefaultOrderedDict([('local_dot_to_dot22', OrderedSet([<theano.gof.opt.TopoOptimizer object at 0x11d22ce10>])), ('TopoOptimizer', OrderedSet([<theano.gof.opt.TopoOptimizer object at 0x11d22ce10>, <theano.gof.opt.TopoOptimizer object at 0x126199610>, <theano.gof.opt.TopoOptimizer object at 0x126199890>, <theano.gof.opt.TopoOptimizer object at 0x1261aa790>])), ('fast_run', OrderedSet([<theano.gof.opt.TopoOptimizer object at 0x11d22ce10>, <theano.tensor.blas.GemmOptimizer object at 0x11d22ce50>, <theano.gof.opt.EquilibriumOptimizer object at 0x1261990d0>, <theano.gof.opt.TopoOptimizer object at 0x126199610>, <theano.gof.opt.TopoOptimizer object at 0x126199890>, <theano.gof.opt.TopoOptimizer object at 0x1261aa790>])), ('fast_compile', OrderedSet([<theano.gof.opt.TopoOptimizer object at 0x11d22ce10>])), ('BlasOpt', OrderedSet([<theano.gof.opt.TopoOptimizer object at 0x11d22ce10>, <theano.tensor.blas.GemmOptimizer object at 0x11d22ce50>, <theano.gof.opt.EquilibriumOptimizer object at 0x1261990d0>, <theano.gof.opt.TopoOptimizer object at 0x126199610>, <theano.gof.opt.TopoOptimizer object at 0x126199890>, <theano.gof.opt.TopoOptimizer object at 0x1261aa790>])), ('gemm_optimizer', OrderedSet([<theano.tensor.blas.GemmOptimizer object at 0x11d22ce50>])), ('GemmOptimizer', OrderedSet([<theano.tensor.blas.GemmOptimizer object at 0x11d22ce50>])), ('local_gemm_to_gemv', OrderedSet([<theano.gof.opt.EquilibriumOptimizer object at 0x1261990d0>])), ('EquilibriumOptimizer', OrderedSet([<theano.gof.opt.EquilibriumOptimizer object at 0x1261990d0>])), ('local_dot22_to_dot22scalar', OrderedSet([<theano.gof.opt.TopoOptimizer object at 0x126199610>])), ('scipy_blas', OrderedSet([<theano.gof.opt.TopoOptimizer object at 0x126199890>])), ('use_c_blas', OrderedSet([<theano.gof.opt.TopoOptimizer object at 0x1261aa790>])), ('c_blas', OrderedSet([<theano.gof.opt.TopoOptimizer object at 0x1261aa790>]))])

ERROR (theano.gof.opt): Traceback:
ERROR (theano.gof.opt): Traceback (most recent call last):
  File "/Volumes/Transcend/opt/anaconda3/envs/theano/lib/python2.7/site-packages/theano/gof/opt.py", line 251, in apply
    sub_prof = optimizer.optimize(fgraph)
AttributeError: 'SequenceDB' object has no attribute 'optimize'

ERROR (theano.gof.opt): SeqOptimizer apply <theano.gof.optdb.EquilibriumDB object at 0x114e12b50>
ERROR (theano.gof.opt): Traceback:
ERROR (theano.gof.opt): Traceback (most recent call last):
  File "/Volumes/Transcend/opt/anaconda3/envs/theano/lib/python2.7/site-packages/theano/gof/opt.py", line 251, in apply
    sub_prof = optimizer.optimize(fgraph)
AttributeError: 'EquilibriumDB' object has no attribute 'optimize'

ERROR (theano.gof.opt): SeqOptimizer apply <theano.gof.optdb.EquilibriumDB object at 0x114e12bd0>
ERROR (theano.gof.opt): Traceback:
ERROR (theano.gof.opt): Traceback (most recent call last):
  File "/Volumes/Transcend/opt/anaconda3/envs/theano/lib/python2.7/site-packages/theano/gof/opt.py", line 251, in apply
    sub_prof = optimizer.optimize(fgraph)
AttributeError: 'EquilibriumDB' object has no attribute 'optimize'

ERROR (theano.gof.opt): SeqOptimizer apply <theano.gof.optdb.EquilibriumDB object at 0x114e12c90>
ERROR (theano.gof.opt): Traceback:
ERROR (theano.gof.opt): Traceback (most recent call last):
  File "/Volumes/Transcend/opt/anaconda3/envs/theano/lib/python2.7/site-packages/theano/gof/opt.py", line 251, in apply
    sub_prof = optimizer.optimize(fgraph)
AttributeError: 'EquilibriumDB' object has no attribute 'optimize'

ERROR (theano.gof.opt): SeqOptimizer apply <theano.gof.opt.EquilibriumOptimizer object at 0x140056350>
ERROR (theano.gof.opt): Traceback:
ERROR (theano.gof.opt): Traceback (most recent call last):
  File "/Volumes/Transcend/opt/anaconda3/envs/theano/lib/python2.7/site-packages/theano/gof/opt.py", line 251, in apply
    sub_prof = optimizer.optimize(fgraph)
  File "/Volumes/Transcend/opt/anaconda3/envs/theano/lib/python2.7/site-packages/theano/gof/opt.py", line 93, in optimize
    self.add_requirements(fgraph)
  File "/Volumes/Transcend/opt/anaconda3/envs/theano/lib/python2.7/site-packages/theano/gof/opt.py", line 2388, in add_requirements
    opt.add_requirements(fgraph)
AttributeError: 'LocalGroupDB' object has no attribute 'add_requirements'

ERROR (theano.gof.opt): SeqOptimizer apply SequenceDB (id 4783573072)
  position [('local_add_mul_fusion', 0), ('composite_elemwise_fusion', 1)]
  names set(['local_add_mul_fusion', 'composite_elemwise_fusion'])
  db DefaultOrderedDict([('local_add_mul_fusion', OrderedSet([<theano.tensor.opt.FusionOptimizer object at 0x11d1f8890>])), ('FusionOptimizer', OrderedSet([<theano.tensor.opt.FusionOptimizer object at 0x11d1f8890>, <theano.tensor.opt.FusionOptimizer object at 0x11d1f8950>])), ('fast_run', OrderedSet([<theano.tensor.opt.FusionOptimizer object at 0x11d1f8890>, <theano.tensor.opt.FusionOptimizer object at 0x11d1f8950>])), ('fusion', OrderedSet([<theano.tensor.opt.FusionOptimizer object at 0x11d1f8890>, <theano.tensor.opt.FusionOptimizer object at 0x11d1f8950>])), ('composite_elemwise_fusion', OrderedSet([<theano.tensor.opt.FusionOptimizer object at 0x11d1f8950>]))])

ERROR (theano.gof.opt): Traceback:
ERROR (theano.gof.opt): Traceback (most recent call last):
  File "/Volumes/Transcend/opt/anaconda3/envs/theano/lib/python2.7/site-packages/theano/gof/opt.py", line 251, in apply
    sub_prof = optimizer.optimize(fgraph)
AttributeError: 'SequenceDB' object has no attribute 'optimize'

loading data... data loaded!
model architecture: CNN-non-static
using: word2vec vectors
[('image shape', 64, 300), ('filter shape', [(100, 1, 3, 300), (100, 1, 4, 300), (100, 1, 5, 300)]), ('hidden_units', [100, 2]), ('dropout', [0.5]), ('batch_size', 50), ('non_static', True), ('learn_decay', 0.95), ('conv_non_linear', 'relu'), ('non_static', True), ('sqr_norm_lim', 9), ('shuffle_batch', True)]
... training
epoch: 1, training time: 298.33 secs, train perf: 81.55 %, val perf: 78.11 %
epoch: 2, training time: 298.12 secs, train perf: 82.68 %, val perf: 74.42 %
epoch: 3, training time: 301.75 secs, train perf: 91.78 %, val perf: 81.79 %
epoch: 4, training time: 300.32 secs, train perf: 95.87 %, val perf: 80.42 %
epoch: 5, training time: 300.05 secs, train perf: 96.24 %, val perf: 82.74 %
cv: 0, perf: 0.800186741363212
0.800186741363212