ERROR (theano.gof.opt): SeqOptimizer apply <theano.gof.optdb.EquilibriumDB object at 0x124788410>
ERROR (theano.gof.opt): Traceback:
ERROR (theano.gof.opt): Traceback (most recent call last):
  File "/Volumes/Transcend/opt/anaconda3/envs/theano/lib/python2.7/site-packages/theano/gof/opt.py", line 251, in apply
    sub_prof = optimizer.optimize(fgraph)
AttributeError: 'EquilibriumDB' object has no attribute 'optimize'

ERROR (theano.gof.opt): SeqOptimizer apply <theano.gof.opt.EquilibriumOptimizer object at 0x134629790>
ERROR (theano.gof.opt): Traceback:
ERROR (theano.gof.opt): Traceback (most recent call last):
  File "/Volumes/Transcend/opt/anaconda3/envs/theano/lib/python2.7/site-packages/theano/gof/opt.py", line 251, in apply
    sub_prof = optimizer.optimize(fgraph)
  File "/Volumes/Transcend/opt/anaconda3/envs/theano/lib/python2.7/site-packages/theano/gof/opt.py", line 93, in optimize
    self.add_requirements(fgraph)
  File "/Volumes/Transcend/opt/anaconda3/envs/theano/lib/python2.7/site-packages/theano/gof/opt.py", line 2388, in add_requirements
    opt.add_requirements(fgraph)
AttributeError: 'SequenceDB' object has no attribute 'add_requirements'

ERROR (theano.gof.opt): SeqOptimizer apply <theano.gof.optdb.TopoDB object at 0x113097550>
ERROR (theano.gof.opt): Traceback:
ERROR (theano.gof.opt): Traceback (most recent call last):
  File "/Volumes/Transcend/opt/anaconda3/envs/theano/lib/python2.7/site-packages/theano/gof/opt.py", line 251, in apply
    sub_prof = optimizer.optimize(fgraph)
AttributeError: 'TopoDB' object has no attribute 'optimize'

ERROR (theano.gof.opt): SeqOptimizer apply <theano.gof.optdb.EquilibriumDB object at 0x113097690>
ERROR (theano.gof.opt): Traceback:
ERROR (theano.gof.opt): Traceback (most recent call last):
  File "/Volumes/Transcend/opt/anaconda3/envs/theano/lib/python2.7/site-packages/theano/gof/opt.py", line 251, in apply
    sub_prof = optimizer.optimize(fgraph)
AttributeError: 'EquilibriumDB' object has no attribute 'optimize'

ERROR (theano.gof.opt): SeqOptimizer apply <theano.gof.optdb.EquilibriumDB object at 0x113097a50>
ERROR (theano.gof.opt): Traceback:
ERROR (theano.gof.opt): Traceback (most recent call last):
  File "/Volumes/Transcend/opt/anaconda3/envs/theano/lib/python2.7/site-packages/theano/gof/opt.py", line 251, in apply
    sub_prof = optimizer.optimize(fgraph)
AttributeError: 'EquilibriumDB' object has no attribute 'optimize'

ERROR (theano.gof.opt): SeqOptimizer apply <theano.gof.optdb.EquilibriumDB object at 0x124794510>
ERROR (theano.gof.opt): Traceback:
ERROR (theano.gof.opt): Traceback (most recent call last):
  File "/Volumes/Transcend/opt/anaconda3/envs/theano/lib/python2.7/site-packages/theano/gof/opt.py", line 251, in apply
    sub_prof = optimizer.optimize(fgraph)
AttributeError: 'EquilibriumDB' object has no attribute 'optimize'

ERROR (theano.gof.opt): SeqOptimizer apply SequenceDB (id 4751787600)
  position [('local_dot_to_dot22', 0), ('gemm_optimizer', 10), ('local_dot22_to_dot22scalar', 11), ('local_gemm_to_gemv', 15), ('use_c_blas', 20), ('scipy_blas', 100)]
  names set(['gemm_optimizer', 'local_gemm_to_gemv', 'local_dot_to_dot22', 'scipy_blas', 'use_c_blas', 'local_dot22_to_dot22scalar'])
  db DefaultOrderedDict([('local_dot_to_dot22', OrderedSet([<theano.gof.opt.TopoOptimizer object at 0x11b3a8e10>])), ('TopoOptimizer', OrderedSet([<theano.gof.opt.TopoOptimizer object at 0x11b3a8e10>, <theano.gof.opt.TopoOptimizer object at 0x124315610>, <theano.gof.opt.TopoOptimizer object at 0x124315890>, <theano.gof.opt.TopoOptimizer object at 0x124326790>])), ('fast_run', OrderedSet([<theano.gof.opt.TopoOptimizer object at 0x11b3a8e10>, <theano.tensor.blas.GemmOptimizer object at 0x11b3a8e50>, <theano.gof.opt.EquilibriumOptimizer object at 0x1243150d0>, <theano.gof.opt.TopoOptimizer object at 0x124315610>, <theano.gof.opt.TopoOptimizer object at 0x124315890>, <theano.gof.opt.TopoOptimizer object at 0x124326790>])), ('fast_compile', OrderedSet([<theano.gof.opt.TopoOptimizer object at 0x11b3a8e10>])), ('BlasOpt', OrderedSet([<theano.gof.opt.TopoOptimizer object at 0x11b3a8e10>, <theano.tensor.blas.GemmOptimizer object at 0x11b3a8e50>, <theano.gof.opt.EquilibriumOptimizer object at 0x1243150d0>, <theano.gof.opt.TopoOptimizer object at 0x124315610>, <theano.gof.opt.TopoOptimizer object at 0x124315890>, <theano.gof.opt.TopoOptimizer object at 0x124326790>])), ('gemm_optimizer', OrderedSet([<theano.tensor.blas.GemmOptimizer object at 0x11b3a8e50>])), ('GemmOptimizer', OrderedSet([<theano.tensor.blas.GemmOptimizer object at 0x11b3a8e50>])), ('local_gemm_to_gemv', OrderedSet([<theano.gof.opt.EquilibriumOptimizer object at 0x1243150d0>])), ('EquilibriumOptimizer', OrderedSet([<theano.gof.opt.EquilibriumOptimizer object at 0x1243150d0>])), ('local_dot22_to_dot22scalar', OrderedSet([<theano.gof.opt.TopoOptimizer object at 0x124315610>])), ('scipy_blas', OrderedSet([<theano.gof.opt.TopoOptimizer object at 0x124315890>])), ('use_c_blas', OrderedSet([<theano.gof.opt.TopoOptimizer object at 0x124326790>])), ('c_blas', OrderedSet([<theano.gof.opt.TopoOptimizer object at 0x124326790>]))])

ERROR (theano.gof.opt): Traceback:
ERROR (theano.gof.opt): Traceback (most recent call last):
  File "/Volumes/Transcend/opt/anaconda3/envs/theano/lib/python2.7/site-packages/theano/gof/opt.py", line 251, in apply
    sub_prof = optimizer.optimize(fgraph)
AttributeError: 'SequenceDB' object has no attribute 'optimize'

ERROR (theano.gof.opt): SeqOptimizer apply <theano.gof.optdb.EquilibriumDB object at 0x113097b50>
ERROR (theano.gof.opt): Traceback:
ERROR (theano.gof.opt): Traceback (most recent call last):
  File "/Volumes/Transcend/opt/anaconda3/envs/theano/lib/python2.7/site-packages/theano/gof/opt.py", line 251, in apply
    sub_prof = optimizer.optimize(fgraph)
AttributeError: 'EquilibriumDB' object has no attribute 'optimize'

ERROR (theano.gof.opt): SeqOptimizer apply <theano.gof.optdb.EquilibriumDB object at 0x113097bd0>
ERROR (theano.gof.opt): Traceback:
ERROR (theano.gof.opt): Traceback (most recent call last):
  File "/Volumes/Transcend/opt/anaconda3/envs/theano/lib/python2.7/site-packages/theano/gof/opt.py", line 251, in apply
    sub_prof = optimizer.optimize(fgraph)
AttributeError: 'EquilibriumDB' object has no attribute 'optimize'

ERROR (theano.gof.opt): SeqOptimizer apply <theano.gof.optdb.EquilibriumDB object at 0x113097c90>
ERROR (theano.gof.opt): Traceback:
ERROR (theano.gof.opt): Traceback (most recent call last):
  File "/Volumes/Transcend/opt/anaconda3/envs/theano/lib/python2.7/site-packages/theano/gof/opt.py", line 251, in apply
    sub_prof = optimizer.optimize(fgraph)
AttributeError: 'EquilibriumDB' object has no attribute 'optimize'

ERROR (theano.gof.opt): SeqOptimizer apply <theano.gof.opt.EquilibriumOptimizer object at 0x1346297d0>
ERROR (theano.gof.opt): Traceback:
ERROR (theano.gof.opt): Traceback (most recent call last):
  File "/Volumes/Transcend/opt/anaconda3/envs/theano/lib/python2.7/site-packages/theano/gof/opt.py", line 251, in apply
    sub_prof = optimizer.optimize(fgraph)
  File "/Volumes/Transcend/opt/anaconda3/envs/theano/lib/python2.7/site-packages/theano/gof/opt.py", line 93, in optimize
    self.add_requirements(fgraph)
  File "/Volumes/Transcend/opt/anaconda3/envs/theano/lib/python2.7/site-packages/theano/gof/opt.py", line 2388, in add_requirements
    opt.add_requirements(fgraph)
AttributeError: 'LocalGroupDB' object has no attribute 'add_requirements'

ERROR (theano.gof.opt): SeqOptimizer apply SequenceDB (id 4751575120)
  position [('local_add_mul_fusion', 0), ('composite_elemwise_fusion', 1)]
  names set(['local_add_mul_fusion', 'composite_elemwise_fusion'])
  db DefaultOrderedDict([('local_add_mul_fusion', OrderedSet([<theano.tensor.opt.FusionOptimizer object at 0x11b374890>])), ('FusionOptimizer', OrderedSet([<theano.tensor.opt.FusionOptimizer object at 0x11b374890>, <theano.tensor.opt.FusionOptimizer object at 0x11b374950>])), ('fast_run', OrderedSet([<theano.tensor.opt.FusionOptimizer object at 0x11b374890>, <theano.tensor.opt.FusionOptimizer object at 0x11b374950>])), ('fusion', OrderedSet([<theano.tensor.opt.FusionOptimizer object at 0x11b374890>, <theano.tensor.opt.FusionOptimizer object at 0x11b374950>])), ('composite_elemwise_fusion', OrderedSet([<theano.tensor.opt.FusionOptimizer object at 0x11b374950>]))])

ERROR (theano.gof.opt): Traceback:
ERROR (theano.gof.opt): Traceback (most recent call last):
  File "/Volumes/Transcend/opt/anaconda3/envs/theano/lib/python2.7/site-packages/theano/gof/opt.py", line 251, in apply
    sub_prof = optimizer.optimize(fgraph)
AttributeError: 'SequenceDB' object has no attribute 'optimize'

ERROR (theano.gof.opt): SeqOptimizer apply <theano.gof.optdb.EquilibriumDB object at 0x124788410>
ERROR (theano.gof.opt): Traceback:
ERROR (theano.gof.opt): Traceback (most recent call last):
  File "/Volumes/Transcend/opt/anaconda3/envs/theano/lib/python2.7/site-packages/theano/gof/opt.py", line 251, in apply
    sub_prof = optimizer.optimize(fgraph)
AttributeError: 'EquilibriumDB' object has no attribute 'optimize'

ERROR (theano.gof.opt): SeqOptimizer apply <theano.gof.opt.EquilibriumOptimizer object at 0x1371ad290>
ERROR (theano.gof.opt): Traceback:
ERROR (theano.gof.opt): Traceback (most recent call last):
  File "/Volumes/Transcend/opt/anaconda3/envs/theano/lib/python2.7/site-packages/theano/gof/opt.py", line 251, in apply
    sub_prof = optimizer.optimize(fgraph)
  File "/Volumes/Transcend/opt/anaconda3/envs/theano/lib/python2.7/site-packages/theano/gof/opt.py", line 93, in optimize
    self.add_requirements(fgraph)
  File "/Volumes/Transcend/opt/anaconda3/envs/theano/lib/python2.7/site-packages/theano/gof/opt.py", line 2388, in add_requirements
    opt.add_requirements(fgraph)
AttributeError: 'SequenceDB' object has no attribute 'add_requirements'

ERROR (theano.gof.opt): SeqOptimizer apply <theano.gof.optdb.TopoDB object at 0x113097550>
ERROR (theano.gof.opt): Traceback:
ERROR (theano.gof.opt): Traceback (most recent call last):
  File "/Volumes/Transcend/opt/anaconda3/envs/theano/lib/python2.7/site-packages/theano/gof/opt.py", line 251, in apply
    sub_prof = optimizer.optimize(fgraph)
AttributeError: 'TopoDB' object has no attribute 'optimize'

ERROR (theano.gof.opt): SeqOptimizer apply <theano.gof.optdb.EquilibriumDB object at 0x113097690>
ERROR (theano.gof.opt): Traceback:
ERROR (theano.gof.opt): Traceback (most recent call last):
  File "/Volumes/Transcend/opt/anaconda3/envs/theano/lib/python2.7/site-packages/theano/gof/opt.py", line 251, in apply
    sub_prof = optimizer.optimize(fgraph)
AttributeError: 'EquilibriumDB' object has no attribute 'optimize'

ERROR (theano.gof.opt): SeqOptimizer apply <theano.gof.optdb.EquilibriumDB object at 0x113097a50>
ERROR (theano.gof.opt): Traceback:
ERROR (theano.gof.opt): Traceback (most recent call last):
  File "/Volumes/Transcend/opt/anaconda3/envs/theano/lib/python2.7/site-packages/theano/gof/opt.py", line 251, in apply
    sub_prof = optimizer.optimize(fgraph)
AttributeError: 'EquilibriumDB' object has no attribute 'optimize'

ERROR (theano.gof.opt): SeqOptimizer apply <theano.gof.optdb.EquilibriumDB object at 0x124794510>
ERROR (theano.gof.opt): Traceback:
ERROR (theano.gof.opt): Traceback (most recent call last):
  File "/Volumes/Transcend/opt/anaconda3/envs/theano/lib/python2.7/site-packages/theano/gof/opt.py", line 251, in apply
    sub_prof = optimizer.optimize(fgraph)
AttributeError: 'EquilibriumDB' object has no attribute 'optimize'

ERROR (theano.gof.opt): SeqOptimizer apply SequenceDB (id 4751787600)
  position [('local_dot_to_dot22', 0), ('gemm_optimizer', 10), ('local_dot22_to_dot22scalar', 11), ('local_gemm_to_gemv', 15), ('use_c_blas', 20), ('scipy_blas', 100)]
  names set(['gemm_optimizer', 'local_gemm_to_gemv', 'local_dot_to_dot22', 'scipy_blas', 'use_c_blas', 'local_dot22_to_dot22scalar'])
  db DefaultOrderedDict([('local_dot_to_dot22', OrderedSet([<theano.gof.opt.TopoOptimizer object at 0x11b3a8e10>])), ('TopoOptimizer', OrderedSet([<theano.gof.opt.TopoOptimizer object at 0x11b3a8e10>, <theano.gof.opt.TopoOptimizer object at 0x124315610>, <theano.gof.opt.TopoOptimizer object at 0x124315890>, <theano.gof.opt.TopoOptimizer object at 0x124326790>])), ('fast_run', OrderedSet([<theano.gof.opt.TopoOptimizer object at 0x11b3a8e10>, <theano.tensor.blas.GemmOptimizer object at 0x11b3a8e50>, <theano.gof.opt.EquilibriumOptimizer object at 0x1243150d0>, <theano.gof.opt.TopoOptimizer object at 0x124315610>, <theano.gof.opt.TopoOptimizer object at 0x124315890>, <theano.gof.opt.TopoOptimizer object at 0x124326790>])), ('fast_compile', OrderedSet([<theano.gof.opt.TopoOptimizer object at 0x11b3a8e10>])), ('BlasOpt', OrderedSet([<theano.gof.opt.TopoOptimizer object at 0x11b3a8e10>, <theano.tensor.blas.GemmOptimizer object at 0x11b3a8e50>, <theano.gof.opt.EquilibriumOptimizer object at 0x1243150d0>, <theano.gof.opt.TopoOptimizer object at 0x124315610>, <theano.gof.opt.TopoOptimizer object at 0x124315890>, <theano.gof.opt.TopoOptimizer object at 0x124326790>])), ('gemm_optimizer', OrderedSet([<theano.tensor.blas.GemmOptimizer object at 0x11b3a8e50>])), ('GemmOptimizer', OrderedSet([<theano.tensor.blas.GemmOptimizer object at 0x11b3a8e50>])), ('local_gemm_to_gemv', OrderedSet([<theano.gof.opt.EquilibriumOptimizer object at 0x1243150d0>])), ('EquilibriumOptimizer', OrderedSet([<theano.gof.opt.EquilibriumOptimizer object at 0x1243150d0>])), ('local_dot22_to_dot22scalar', OrderedSet([<theano.gof.opt.TopoOptimizer object at 0x124315610>])), ('scipy_blas', OrderedSet([<theano.gof.opt.TopoOptimizer object at 0x124315890>])), ('use_c_blas', OrderedSet([<theano.gof.opt.TopoOptimizer object at 0x124326790>])), ('c_blas', OrderedSet([<theano.gof.opt.TopoOptimizer object at 0x124326790>]))])

ERROR (theano.gof.opt): Traceback:
ERROR (theano.gof.opt): Traceback (most recent call last):
  File "/Volumes/Transcend/opt/anaconda3/envs/theano/lib/python2.7/site-packages/theano/gof/opt.py", line 251, in apply
    sub_prof = optimizer.optimize(fgraph)
AttributeError: 'SequenceDB' object has no attribute 'optimize'

ERROR (theano.gof.opt): SeqOptimizer apply <theano.gof.optdb.EquilibriumDB object at 0x113097b50>
ERROR (theano.gof.opt): Traceback:
ERROR (theano.gof.opt): Traceback (most recent call last):
  File "/Volumes/Transcend/opt/anaconda3/envs/theano/lib/python2.7/site-packages/theano/gof/opt.py", line 251, in apply
    sub_prof = optimizer.optimize(fgraph)
AttributeError: 'EquilibriumDB' object has no attribute 'optimize'

ERROR (theano.gof.opt): SeqOptimizer apply <theano.gof.optdb.EquilibriumDB object at 0x113097bd0>
ERROR (theano.gof.opt): Traceback:
ERROR (theano.gof.opt): Traceback (most recent call last):
  File "/Volumes/Transcend/opt/anaconda3/envs/theano/lib/python2.7/site-packages/theano/gof/opt.py", line 251, in apply
    sub_prof = optimizer.optimize(fgraph)
AttributeError: 'EquilibriumDB' object has no attribute 'optimize'

ERROR (theano.gof.opt): SeqOptimizer apply <theano.gof.optdb.EquilibriumDB object at 0x113097c90>
ERROR (theano.gof.opt): Traceback:
ERROR (theano.gof.opt): Traceback (most recent call last):
  File "/Volumes/Transcend/opt/anaconda3/envs/theano/lib/python2.7/site-packages/theano/gof/opt.py", line 251, in apply
    sub_prof = optimizer.optimize(fgraph)
AttributeError: 'EquilibriumDB' object has no attribute 'optimize'

ERROR (theano.gof.opt): SeqOptimizer apply <theano.gof.opt.EquilibriumOptimizer object at 0x13cd1b650>
ERROR (theano.gof.opt): Traceback:
ERROR (theano.gof.opt): Traceback (most recent call last):
  File "/Volumes/Transcend/opt/anaconda3/envs/theano/lib/python2.7/site-packages/theano/gof/opt.py", line 251, in apply
    sub_prof = optimizer.optimize(fgraph)
  File "/Volumes/Transcend/opt/anaconda3/envs/theano/lib/python2.7/site-packages/theano/gof/opt.py", line 93, in optimize
    self.add_requirements(fgraph)
  File "/Volumes/Transcend/opt/anaconda3/envs/theano/lib/python2.7/site-packages/theano/gof/opt.py", line 2388, in add_requirements
    opt.add_requirements(fgraph)
AttributeError: 'LocalGroupDB' object has no attribute 'add_requirements'

ERROR (theano.gof.opt): SeqOptimizer apply SequenceDB (id 4751575120)
  position [('local_add_mul_fusion', 0), ('composite_elemwise_fusion', 1)]
  names set(['local_add_mul_fusion', 'composite_elemwise_fusion'])
  db DefaultOrderedDict([('local_add_mul_fusion', OrderedSet([<theano.tensor.opt.FusionOptimizer object at 0x11b374890>])), ('FusionOptimizer', OrderedSet([<theano.tensor.opt.FusionOptimizer object at 0x11b374890>, <theano.tensor.opt.FusionOptimizer object at 0x11b374950>])), ('fast_run', OrderedSet([<theano.tensor.opt.FusionOptimizer object at 0x11b374890>, <theano.tensor.opt.FusionOptimizer object at 0x11b374950>])), ('fusion', OrderedSet([<theano.tensor.opt.FusionOptimizer object at 0x11b374890>, <theano.tensor.opt.FusionOptimizer object at 0x11b374950>])), ('composite_elemwise_fusion', OrderedSet([<theano.tensor.opt.FusionOptimizer object at 0x11b374950>]))])

ERROR (theano.gof.opt): Traceback:
ERROR (theano.gof.opt): Traceback (most recent call last):
  File "/Volumes/Transcend/opt/anaconda3/envs/theano/lib/python2.7/site-packages/theano/gof/opt.py", line 251, in apply
    sub_prof = optimizer.optimize(fgraph)
AttributeError: 'SequenceDB' object has no attribute 'optimize'

ERROR (theano.gof.opt): SeqOptimizer apply <theano.scan_module.scan_opt.ScanInplaceOptimizer object at 0x1247946d0>
ERROR (theano.gof.opt): Traceback:
ERROR (theano.gof.opt): Traceback (most recent call last):
  File "/Volumes/Transcend/opt/anaconda3/envs/theano/lib/python2.7/site-packages/theano/gof/opt.py", line 251, in apply
    sub_prof = optimizer.optimize(fgraph)
  File "/Volumes/Transcend/opt/anaconda3/envs/theano/lib/python2.7/site-packages/theano/gof/opt.py", line 97, in optimize
    ret = self.apply(fgraph, *args, **kwargs)
  File "/Volumes/Transcend/opt/anaconda3/envs/theano/lib/python2.7/site-packages/theano/scan_module/scan_opt.py", line 1013, in apply
    nodes = fgraph.toposort()[::-1]
  File "/Volumes/Transcend/opt/anaconda3/envs/theano/lib/python2.7/site-packages/theano/gof/fg.py", line 639, in toposort
    order = graph.io_toposort(fg.inputs, fg.outputs, ords)
  File "/Volumes/Transcend/opt/anaconda3/envs/theano/lib/python2.7/site-packages/theano/gof/graph.py", line 1102, in io_toposort
    deps_cache=deps_cache, clients=clients)
  File "/Volumes/Transcend/opt/anaconda3/envs/theano/lib/python2.7/site-packages/theano/gof/graph.py", line 1009, in general_toposort
    raise ValueError('graph contains cycles')
ValueError: graph contains cycles

loading data... data loaded!
model architecture: CNN-non-static
using: word2vec vectors
[('image shape', 64, 300), ('filter shape', [(100, 1, 3, 300), (100, 1, 4, 300), (100, 1, 5, 300)]), ('hidden_units', [100, 2]), ('dropout', [0.5]), ('batch_size', 50), ('non_static', True), ('learn_decay', 0.95), ('conv_non_linear', 'relu'), ('non_static', True), ('sqr_norm_lim', 9), ('shuffle_batch', True)]
Traceback (most recent call last):
  File "conv_net_sentence.py", line 325, in <module>
    dropout_rate=[0.5])
  File "conv_net_sentence.py", line 136, in train_conv_net
    allow_input_downcast=True)
  File "/Volumes/Transcend/opt/anaconda3/envs/theano/lib/python2.7/site-packages/theano/compile/function.py", line 317, in function
    output_keys=output_keys)
  File "/Volumes/Transcend/opt/anaconda3/envs/theano/lib/python2.7/site-packages/theano/compile/pfunc.py", line 486, in pfunc
    output_keys=output_keys)
  File "/Volumes/Transcend/opt/anaconda3/envs/theano/lib/python2.7/site-packages/theano/compile/function_module.py", line 1841, in orig_function
    fn = m.create(defaults)
  File "/Volumes/Transcend/opt/anaconda3/envs/theano/lib/python2.7/site-packages/theano/compile/function_module.py", line 1715, in create
    input_storage=input_storage_lists, storage_map=storage_map)
  File "/Volumes/Transcend/opt/anaconda3/envs/theano/lib/python2.7/site-packages/theano/gof/link.py", line 699, in make_thunk
    storage_map=storage_map)[:3]
  File "/Volumes/Transcend/opt/anaconda3/envs/theano/lib/python2.7/site-packages/theano/gof/vm.py", line 1054, in make_all
    order = self.schedule(fgraph)
  File "/Volumes/Transcend/opt/anaconda3/envs/theano/lib/python2.7/site-packages/theano/gof/link.py", line 410, in schedule
    return fgraph.toposort()
  File "/Volumes/Transcend/opt/anaconda3/envs/theano/lib/python2.7/site-packages/theano/gof/fg.py", line 639, in toposort
    order = graph.io_toposort(fg.inputs, fg.outputs, ords)
  File "/Volumes/Transcend/opt/anaconda3/envs/theano/lib/python2.7/site-packages/theano/gof/graph.py", line 1102, in io_toposort
    deps_cache=deps_cache, clients=clients)
  File "/Volumes/Transcend/opt/anaconda3/envs/theano/lib/python2.7/site-packages/theano/gof/graph.py", line 1009, in general_toposort
    raise ValueError('graph contains cycles')
ValueError: graph contains cycles
